Workbook
Name AENTRADA: #REF!
Name AENTRADA: #REF!
Name AENTRADA: #REF!
Name AMOCO: #REF!
Name AMOCO: #REF!
Name AMOCO: #REF!
Name CERQUAN10: #REF!
Name CERQUAN10: #REF!
Name CERQUAN10: #REF!
Name CERQUAN4: #REF!
Name CERQUAN4: #REF!
Name CERQUAN4: #REF!
Name CERQUAN5: #REF!
Name CERQUAN5: #REF!
Name CERQUAN5: #REF!
Name CERQUAN6: #REF!
Name CERQUAN6: #REF!
Name CERQUAN6: #REF!
Name CERQUAN7: #REF!
Name CERQUAN7: #REF!
Name CERQUAN7: #REF!
Name cerquan8: #REF!
Name cerquan8: #REF!
Name cerquan8: #REF!
Name CERQUAN9: #REF!
Name CERQUAN9: #REF!
Name CERQUAN9: #REF!
Name COMPAR: [1]QVEF!$A$1:$W$41
Name CUAL: #REF!
Name CUAL: #REF!
Name CUAL: #REF!
Name EXXON: #REF!
Name EXXON: #REF!
Name EXXON: #REF!
Name EXXONMOBIL: #REF!
Name EXXONMOBIL: #REF!
Name EXXONMOBIL: #REF!
Name FOS_5299_01: #REF!
Name FOS_5299_01: #REF!
Name FOS_5299_01: #REF!
Name KOCH: #REF!
Name KOCH: #REF!
Name KOCH: #REF!
Name LOADSCALE: #REF!
Name LOADSCALE: #REF!
Name LOADSCALE: #REF!
Name LONG_MC_RAD: '[2]HYDROSTATIC TABLE'!#REF!
Name LONG_MC_RAD: '[2]HYDROSTATIC TABLE'!#REF!
Name LONG_MC_RAD: '[2]HYDROSTATIC TABLE'!#REF!
Name LYONDELL: #REF!
Name LYONDELL: #REF!
Name LYONDELL: #REF!
Name MARATHOS: #REF!
Name MARATHOS: #REF!
Name MARATHOS: #REF!
Name MOBIL: #REF!
Name MOBIL: #REF!
Name MOBIL: #REF!
Name OCENSA: #REF!
Name OCENSA: #REF!

Sheet A
A1: U.N. , ECE - DRAUGHT SURVEY CODE
AI2: FORM "A"
A3: DRAUGHT SURVEY REPORT OF CARGO IN BULK | Z3: =+Draft!AN3 -> X | AA3: LOADED
Z4: =+Draft!AN4 -> 0 | AA4: UNLOADED
B5: Corporate identification:
B6: MSL Marine Surveyors And Logistics
B7: Office of the surveyor at:
B8: =+General!A52 -> Villa Bonita, Centro Comercial Villa Plaza Local N 6, Alajuela - Costa Rica
B9: Telephone no: | Q9: Fax no: | AD9: E-mail
B10: =++General!A54 -> 506- 2441 6408 Mobile: 506- 8814 0784 | Q10: =+General!P54 -> 506 - 2441 6408 / 506- 2441 6408 | AD10: =+General!AC54 -> pabel.mslogistics@yahoo.com
B11: Vessel M/V : | Q11: Call letters: | AD11: Survey no:
G12: =+Draft!AB1 -> MV SANTA CAROLINA | T12: =+General!AI3 -> C6WC3 | AG12: =+General!X3 -> 2207-1407-2026
B13: Vessel previous name/s: | AD13: Registry:
B14: =+General!J6 -> 0 | AG14: =+General!M8 -> XXXXX
B15: Built year: | K15: By: | AD15: Flag:
B16: =+General!W8 -> XXXX | K16: =+General!AA8 -> ZHEJIANG OUHUA SHIPBUILDING CO. LTD | AG16: =+General!C8 -> XXXX
B17: Survey requested by: | K17: =+General!AB12 -> MMSL
B18: On the account of: | K18: =+General!AB13 -> 0
B19: REMARKS | F19: =+General!A42 -> 0
B24: This is to certify that the undersigned did, in Bona Fide, attend on board the subject vessel as she lay afloat
B25: at the port of: | H25: =IF(Draft!AN3="X",Draft!AB3,Draft!AB4) -> NEW ORLEANS, LA, EUA | R25: for the purpose of determining by draught computations the
B26: amount of | G26: =+E!Y18&+" MT" -> 51122,54 MT
B27: loaded, unloaded (holds no. | K27: 1 & 3 | W27: ) and having followed the rules as set by the
B28: U.N. / ECE Uniform Code of Standards and Procedures for the Performance of Draught Surveys have the
B29: following to report:
I30: STARTING SURVEY | Z30: FINISHING SURVEY
H31: Attending the surveys: | I31: date D/M/Y: | N31: =+Draft!T2 -> 46217 | Z31: date D/M/Y: | AE31: =+Draft!AS2 -> 46221
I32: hours: from: | N32: =Draft!T3 -> 0.63888889 | R32: to: | T32: =Draft!T4 -> 0.68055556 | Z32: hours: from: | AE32: =Draft!AS3 -> 0.66666667 | AI32: to: | AK32: =Draft!AS4 -> 0.69444444
H33: Name of surveyor/s | J33: =+General!AB10 -> MANFRED BOLAÑOS | AA33: =+General!AB11 -> MANFRED BOLAÑOS
H34: Master | J34: =+General!H10 -> Sunday Val m. Sobremonte | AA34: =+J34 -> Sunday Val m. Sobremonte
AA35: =+J35 -> 0
H36: Chief Officer | J36: =+General!H11 -> Velez Rene Boy Enriquez | AA36: =+J36 -> Velez Rene Boy Enriquez
H37: Chief Engineer | J37: =+General!H12 -> 0 | AA37: =+J37 -> 0
H38: Witness draughts | J38: =+General!H13 -> 0 | AA38: =+J38 -> 0
AA39: =+J39 -> 0
H40: Witness tank sounding | J40: =+General!H14 -> 0 | AA40: =+J40 -> 0
H42: Ship's location | J42: =+General!H16 -> PUERTO CALDERA | AA42: =+General!AB16 -> PUERTO CALDERA
H43: Weather temperature | AA43: 0
H45: Sea condition | J45: =IF(Draft!I32="x","GOOD",IF(Draft!J32="X","LIGHT SHOPPY",IF(Draft!K32="X","HEAVY SHOPPY / SWELL"," "))) -> LIGHT SHOPPY | AA45: =IF(Draft!I33="x","GOOD",IF(Draft!J33="X","LIGHT SHOPPY",IF(Draft!K33="X","HEAVY SHOPPY / SWELL"," "))) -> LIGHT SHOPPY
H46: Heading of ship | J46: =IF(Draft!A8=0,0,"ALONGSIDE BERTH") -> ALONGSIDE BERTH | AA46: =IF(Draft!Z8=0,0,"ALONGSIDE BERTH") -> ALONGSIDE BERTH
...

Sheet B
A1: U.N. , ECE - DRAUGHT SURVEY CODE
AI2: FORM "B"
A3: DRAUGHT SURVEY REPORT OF CARGO IN BULK | Z3: =+A!Z3 -> X | AA3: LOADED
Z4: =+A!Z4 -> 0 | AA4: UNLOADED
B5: Corporate identification:
A6: =A!B6 -> MSL Marine Surveyors And Logistics
B7: Vessel M/V : | Z7: Survey no:
F8: =+A!G12 -> MV SANTA CAROLINA | AC8: =+A!AG12 -> 2207-1407-2026
A9: General remarks by the surveyor/s
E11: Correction for stem and stern obtained by: | Y11: =+General!W34 -> X | Z11: calculation | AF11: =+General!AC34 -> 0 | AG11: tables
E12: Correction for trim (1) obtained by: | Y12: =+General!W35 -> X | Z12: calculation | AF12: =+General!AC35 -> 0 | AG12: tables
E13: Correction for trim (2) obtained by: | Y13: =+General!W36 -> X | Z13: calculation | AF13: =+General!AC36 -> 0 | AG13: tables
E14: Correction due to trim for liquid applied at: | Y14: =+General!W37 -> 0 | Z14: soundings | AF14: =+General!AC37 -> X | AG14: volumes
E15: Correction due to trim for liquid obtained by: | Y15: =+General!W38 -> X | Z15: calculation | AF15: =+General!AC38 -> 0 | AG15: tables
B17: Initial Draft Survey Remarks
B18: =+Draft!A37 -> REMARK: Swell Condition, Initial ( 0,10 to 0.20 Mtr) / Final Draft ( 0,10 to 0,20 Mtr)
B19: Final Draft Survey Remarks
B20: =+Draft!AB37 -> 0
A21: Ship's approved hydrostatic tables and lightship information issued by and dated:
B22: =+General!A28 -> ABS JAN 12 /2001
B24: Degree of tank calibration complies with code: | W24: =+General!W39 -> X | X24: Yes | AA24: =+General!AC39 -> 0 | AB24: No
B26: Range of trim correction tables available
B27: =IF(General!B30="X","YES",General!J30) -> YES
B28: Shipyard no. | S28: Hull no : | AC28: Dated at:
B30: Surveyor remarks on ship's documents
N32: metres | AE32: metric tonnes
A33: Length overall | N33: =+General!M18 -> 189.99 | T33: Constant declared | AE33: =+General!AG18 -> 220
A34: Length between p.p. | N34: =+General!M19 -> 182.96 | T34: Constant calculated | AE34: =+General!AG19 -> 300
A35: Extreme breadth | N35: =+General!M20 -> 0 | T35: Light displacement | AE35: =+General!AG20 -> 10787
A36: Moulded breadth | N36: =+General!M21 -> 28.3 | T36: Light shipweight (plan) | AE36: =+General!AG21 -> 10787
A37: Depth overall incl.. keel plate | N37: =+General!M22 -> 0 | T37: Summer displacement | AE37: =+General!AG22 -> 46970
A38: Moulded depth | N38: =+General!M23 -> 18.2 | T38: Summer deadweight | AE38: =+General!AG23 -> 37205
A39: Summer draught | N39: =+General!M24 -> 10.5 | T39: Net register tons | AE39: =+General!AG24 -> 12205
A40: Summer freeboard | N40: =+General!M25 -> 4.732 | T40: Gross register Tons | AE40: =+General!AG25 -> 24196
S42: STARTING SURVEY | AC42: FINISHING SURVEY | AD42: FINISHING SURVEY
A43: Tonnes per Centimetre Immersion | S43: =+Draft!E16 -> 59.643231 | AC43: =+Draft!AD16 -> 55.118545
A44: Longitudinal Centre of Flotation | S44: =+Draft!A16 -> 1.5318167 | AC44: =+Draft!Z16 -> -6.1080068
A45: Distance marks forward pp. (forward - aft+) | S45: =+Draft!V8 -> 3.48 | AC45: =+Draft!AU8 -> 3.48
A46: Distance marks after pp. (forward - aft+) | S46: =+Draft!V10 -> 13.95 | AC46: =+Draft!AU10 -> 13.95
A47: Distance marks midship pp. (forward - aft+) | S47: =+Draft!V9 -> 0.5 | AC47: =+Draft!AU9 -> 0.5
...

Sheet C
A1: U.N. , ECE - DRAUGHT SURVEY CODE
AI2: FORM "C"
A3: DRAUGHT SURVEY REPORT OF CARGO IN BULK | Z3: =+A!Z3 -> X | AA3: LOADED
Z4: =+A!Z4 -> 0 | AA4: UNLOADED
B5: Corporate identification:
A6: =A!B6 -> MSL Marine Surveyors And Logistics
B7: Vessel M/V : | Z7: Survey no:
F8: =+A!G12 -> MV SANTA CAROLINA | AC8: =+A!AG12 -> 2207-1407-2026
A9: DRAUGHT STATEMENT
A11: DRAUGHT READINGS HOURS: | S11: STARTING SURVEY | AE11: FINISHING SURVEY
S12: From | U12: =Draft!T3 -> 0.63888889 | X12: To | Y12: =Draft!T4 -> 0.68055556 | AE12: From | AG12: =Draft!AS3 -> 0.66666667 | AJ12: To | AK12: =Draft!AS4 -> 0.69444444
S13: metres | AE13: metres
B14: Draught forward port | S14: =+Draft!A8 -> 11.43 | AE14: =+Draft!Z8 -> 4.65
B15: Draught forward starboard | S15: =+Draft!E8 -> 11.44 | AE15: =+Draft!AD8 -> 4.65
B16: Draught forward mean | S16: =+Draft!J8 -> 11.435 | AE16: =+Draft!AI8 -> 4.65
B17: Stem correction | S17: =+Draft!N8 -> -0.014769643 | AE17: =+Draft!AM8 -> -0.044697604
B18: Draught forward (corrected to fore pp.) | S18: =+Draft!R8 -> 11.42023 | AE18: =+Draft!AQ8 -> 4.6053024
B19: Draught after port | S19: =+Draft!A10 -> 12.19 | AE19: =+Draft!Z10 -> 6.95
B20: Draught after starboard | S20: =+Draft!E10 -> 12.2 | AE20: =+Draft!AD10 -> 6.95
B21: Draught after mean | S21: =+Draft!J10 -> 12.195 | AE21: =+Draft!AI10 -> 6.95
B22: Stem correction | S22: =+Draft!N10 -> 0.059205897 | AE22: =+Draft!AM10 -> 0.17917574
B23: Draught after (corrected to after pp.) | S23: =+Draft!R10 -> 12.254206 | AE23: =+Draft!AQ10 -> 7.1291757
B24: Drought fore & after mean | S24: =(+S18+S23)/2 -> 11.837218 | AE24: =(+AE18+AE23)/2 -> 5.8672391
B25: Draught midship port | S25: =+Draft!A9 -> 11.78 | AE25: =+Draft!Z9 -> 5.76
B26: Drought midship starboard | S26: =+Draft!E9 -> 11.79 | AE26: =+Draft!AD9 -> 5.76
B27: Draught midship mean | S27: =+Draft!J9 -> 11.785 | AE27: =+Draft!AI9 -> 5.76
B28: miadship correction | S28: =+Draft!N9 -> -0.0021220752 | AE28: =+Draft!AM9 -> -0.0064220696
B29: Draught midship (corrected to midship pp.) | S29: =+Draft!R9 -> 11.782878 | AE29: =+Draft!AQ9 -> 5.7535779
B30: Sag (+) Hog (-) | S30: =+S27-(S16+S21)/2 -> -0.03 | T30: =+T27-(T16+T21)/2 -> 0 | U30: =+U27-(U16+U21)/2 -> 0 | V30: =+V27-(V16+V21)/2 -> 0 | W30: =+W27-(W16+W21)/2 -> 0 | X30: =+X27-(X16+X21)/2 -> 0 | Y30: =+Y27-(Y16+Y21)/2 -> 0 | Z30: =+Z27-(Z16+Z21)/2 -> 0 | AE30: =+AE27-(AE16+AE21)/2 -> -0.04 | AF30: =+AF27-(AF16+AF21)/2 -> 0 | AG30: =+AG27-(AG16+AG21)/2 -> 0 | AH30: =+AH27-(AH16+AH21)/2 -> 0 | AI30: =+AI27-(AI16+AI21)/2 -> 0 | AJ30: =+AJ27-(AJ16+AJ21)/2 -> 0 | AK30: =+AK27-(AK16+AK21)/2 -> 0 | AL30: =+AL27-(AL16+AL21)/2 -> 0
B31: Mean of means | S31: =+Draft!R13 -> 11.796463 | AE31: =+Draft!AQ13 -> 5.7819932
B32: Draughl extreme corrected for hog/sag | S32: Nil | AE32: Nil
B33: Correction (-) for keel tickness it applicable | S33: =+S32 -> Nil | AE33: =+AE32 -> Nil
B34: Draught moulded corrected for hog/sag | S34: =+S33 -> Nil | AE34: =+AE33 -> Nil
B35: (Note: Utilize line 152 or line 154) | S35: =+S34 -> Nil | AE35: =+AE34 -> Nil
B36: Trim: fwd(-) aft(+) | S36: =+Draft!E13 -> 0.83397554 | AE36: =+Draft!AD13 -> 2.5238733
S37: Kg/m3 | AE37: Kg/m3
B38: Observed density | S38: =+Draft!I13 -> 1.019 | AE38: =+Draft!AH13 -> 1.019
B39: (Ship's tables density Kg/m3 1.025 )
G40: Hydrometer no | M40: =+General!L32 -> 1234564555
S41: Metric tonnes | AE41: Metric tonnes
...

Sheet General
S1: Vessel M/V : | X1: MV SANTA CAROLINA
S3: Survey no: | X3: 2207-1407-2026 | AE3: Call letters: | AI3: C6WC3
A6: Vessel previous name/s:
A8: Flag: | C8: XXXX | I8: Registry: | M8: XXXXX | S8: Built year: | W8: XXXX | Y8: By: | AA8: ZHEJIANG OUHUA SHIPBUILDING CO. LTD
A10: Master | H10: Sunday Val m. Sobremonte | T10: Initial Surveyor/s | AB10: MANFRED BOLAÑOS
A11: Chief Officer | H11: Velez Rene Boy Enriquez | T11: Final Surveyor/s | AB11: MANFRED BOLAÑOS
A12: Chief Engineer | T12: Survey requested by: | AB12: MMSL
A13: Witness draughts | H13: 0 | T13: On the account of:
A14: Witness sounding | H14: 0 | T14: Attended also by: | AB14: MSLOGISTICS
A16: Init Ship's location | H16: PUERTO CALDERA | T16: Final Ship's location | AB16: PUERTO CALDERA
A18: Length overall | M18: 189.99 | T18: Constant declared | AG18: 220
A19: Length between p.p. | M19: 182.96 | T19: Constant calculated | AG19: =+Draft!M30 -> 300
A20: Extreme breadth | T20: Light displacement | AG20: =+Draft!M29 -> 10787
A21: Moulded breadth | M21: 28.3 | T21: Light shipweight (plan) | AG21: =Draft!M29 -> 10787
A22: Depth overall incl.. keel plate | T22: Summer displacement | AG22: 46970
A23: Moulded depth | M23: 18.2 | T23: Summer deadweight | AG23: 37205
A24: Summer draught | M24: 10.5 | T24: Net register tons | AG24: 12205
A25: Summer freeboard | M25: 4.732 | T25: Gross register Tons | AG25: 24196
A27: Ship's approved hydrostatic tables and lightship information issued by and dated:
A28: ABS JAN 12 /2001
B29: Range of trim correction tables available
B30: X | C30: YES | H30: NO
F32: Hydrometer no | L32: 1234564555
F34: Correction for stem and stern obtained by: | W34: X | X34: calculation | AD34: tables | BC34: ARRIVAL TRIM CORRECTIONS FOR TANKS IS NOT COVERED BY VESSEL´S TABLES
F35: Correction for trim (1) obtained by: | W35: X | X35: calculation | AD35: tables
F36: Correction for trim (2) obtained by: | W36: X | X36: calculation | AD36: tables
F37: Correction due to trim for liquid applied at: | X37: soundings | AC37: X | AD37: volumes | BC37: The vessel should arrive with a trim out of the limits of trim covered by the trim corrections of the sounding tables and ballast tanks in slack conditions, and the Aft draft was not visible and properly referenced; due to previous fails at arrival, THE INITIAL OBTAINED FIGURE IS NOT RELIABLE. In addition, for the Final Draft, some ballast tanks were partially ballasted. THE ABNORMAL ARRIVAL CONDITION CAUSE THAT DRAFT SURVEY FIGURE ARE NOT RELIABLE, AND CAN´T BE USED AS LOADED/DISCHARGED CARGO FIGURE
F38: Correction due to trim for liquid obtained by: | W38: X | X38: calculation | AD38: tables
F39: Degree of tank calibration complies with code: | W39: X | X39: Yes | AD39: No
A41: Remarks regarding reliability of calculations
A51: Office of the surveyor at:
A52: Villa Bonita, Centro Comercial Villa Plaza Local N 6, Alajuela - Costa Rica
A53: Telephone no: | P53: Fax no: | AC53: E-mail
A54: 506- 2441 6408 Mobile: 506- 8814 0784 | P54: 506 - 2441 6408 / 506- 2441 6408 | AC54: pabel.mslogistics@yahoo.com

Sheet Draft
Q1: INITIAL SURVEY | AB1: =General!X1 -> MV SANTA CAROLINA | AP1: FINAL SURVEY
Q2: DATE | T2: 46217 | Y2: CARGO | AB2: DDGS-SOYABEANS-YELLOW CORN | AP2: DATE | AS2: 46221 | BB2: DISPL'S | BC2: LCF | BD2: MTC | BE2: APF | BG2: DRAFT | BH2: DISP | BI2: LCF | BJ2: MTC- | BK2: MTC+
Q3: FROM | T3: 0.63888889 | Y3: FROM | AB3: NEW ORLEANS, LA, EUA | AI3: LOADING | AN3: X | AP3: FROM | AS3: 0.66666667 | BA3: 1 | BB3: 4575.3 | BC3: =AL13/2-BF3 -> -8.563 | BD3: 481 | BE3: =+BE4-(BE5-BE4) -> 0 | BF3: 106.813 | BG3: =INT(BG4-1) -> 10 | BH3: =VLOOKUP(BG3,TABLAS,2) -> 53901.1 | BI3: =VLOOKUP(BG3,TABLAS,3) -> 2.485 | BJ3: =VLOOKUP(BG4-1.5,TABLAS,4) -> 848.2 | BK3: =VLOOKUP(BG4-1+0.5+0.5,TABLAS,4) -> 891.5
Q4: TO | T4: 0.68055556 | Y4: TO | AB4: PUERTO CALDERA - COSTA RICA | AI4: UNLOADING | AP4: TO | AS4: 0.69444444 | BA4: 2 | BB4: 9536.2 | BC4: =AL13/2-BF4 -> -8.105 | BD4: 540.8 | BE4: =+BE5-(BE6-BE5) -> 0 | BF4: 106.355 | BG4: =+R13 -> 11.796463 | BH4: =VLOOKUP(BG4,TABLAS,2) -> 59939.7 | BI4: =VLOOKUP(BG4,TABLAS,3) -> 4.085 | BJ4: =VLOOKUP(BG4-0.5,TABLAS,4) -> 891.5 | BK4: =VLOOKUP(BG4+0.5,TABLAS,4) -> 909.1
Q5: : | BA5: 3 | BB5: 14695.8 | BC5: =AL13/2-BF5 -> -7.473 | BD5: 582.2 | BF5: 105.723 | BG5: =INT(1+BG4) -> 12 | BH5: =VLOOKUP(BG5,TABLAS,2) -> 66047 | BI5: =VLOOKUP(BG5,TABLAS,3) -> 4.698 | BJ5: =VLOOKUP(BG4-0.5+1,TABLAS,4) -> 909.1 | BK5: =VLOOKUP(BG4+1.5,TABLAS,4) -> 920.1
A6: I N I T I A L D R A F T S U R V E Y | Z6: F I N A L D R A F T S U R V E Y | BA6: 4 | BB6: 19987.8 | BC6: =AL13/2-BF6 -> -6.791 | BD6: 613 | BF6: 105.041
A7: PORT | F7: STB | J7: MEAN | N7: Crrn. | R7: TRUE | V7: Marks | Z7: PORT | AE7: STB | AI7: MEAN | AM7: Crrn. | AQ7: TRUE | AU7: Marks | BA7: 5 | BB7: 25386.3 | BC7: =AL13/2-BF7 -> -5.742 | BD7: 645.6 | BE7: =+BE6-BE5+BE6 -> 0 | BF7: 103.992 | BG7: DRAFT | BH7: DISP | BI7: LCF | BJ7: MTC- | BK7: MTC+
A8: 11.43 | E8: 11.44 | J8: =(A8+E8)/2 -> 11.435 | N8: =IF(A8=0,0,(+A13*-V8/(M13-V8-V10))) -> -0.014769643 | R8: =+J8+N8 -> 11.42023 | V8: 3.48 | Z8: 4.65 | AD8: 4.65 | AI8: =(Z8+AD8)/2 -> 4.65 | AM8: =IF(Z8=0,0,(+Z13*-AU8/(AL13-AU8-AU10))) -> -0.044697604 | AQ8: =+AI8+AM8 -> 4.6053024 | AU8: =V8 -> 3.48 | BA8: 6 | BB8: 30889.1 | BC8: =AL13/2-BF8 -> -4.503 | BD8: 678.4 | BE8: =+BE7-BE6+BE7 -> 0 | BF8: 102.753 | BG8: =INT(BG9-1) -> 4 | BH8: =VLOOKUP(BG8,TABLAS,2) -> 19987.8 | BI8: =VLOOKUP(BG8,TABLAS,3) -> -6.791 | BJ8: =VLOOKUP(BG9-1.5,TABLAS,4) -> 613 | BK8: =VLOOKUP(BG9-1+0.5+0.5,TABLAS,4) -> 645.6
A9: 11.78 | E9: 11.79 | J9: =(A9+E9)/2 -> 11.785 | N9: =IF(A8=0,0,(+A13*-V9/(M13-V8-V10))) -> -0.0021220752 | R9: =+J9+N9 -> 11.782878 | V9: 0.5 | Z9: 5.76 | AD9: 5.76 | AI9: =(Z9+AD9)/2 -> 5.76 | AM9: =IF(Z8=0,0,(+Z13*-AU9/(AL13-AU8-AU10))) -> -0.0064220696 | AQ9: =+AI9+AM9 -> 5.7535779 | AU9: =V9 -> 0.5 | BA9: 7 | BB9: 36483.7 | BC9: =AL13/2-BF9 -> -3.028 | BD9: 713 | BE9: =+BE8-BE7+BE8 -> 0 | BF9: 101.278 | BG9: =+AQ13 -> 5.7819932 | BH9: =VLOOKUP(BG9,TABLAS,2) -> 25386.3 | BI9: =VLOOKUP(BG9,TABLAS,3) -> -5.742 | BJ9: =VLOOKUP(BG9-0.5,TABLAS,4) -> 645.6 | BK9: =VLOOKUP(BG9+0.5,TABLAS,4) -> 678.4
A10: 12.19 | E10: 12.2 | J10: =(A10+E10)/2 -> 12.195 | N10: =IF(A8=0,0,(+A13*V10/(M13-V8-V10))) -> 0.059205897 | R10: =+J10+N10 -> 12.254206 | V10: 13.95 | Z10: 6.95 | AD10: 6.95 | AI10: =(Z10+AD10)/2 -> 6.95 | AM10: =IF(Z8=0,0,(+Z13*AU10/(AL13-AU8-AU10))) -> 0.17917574 | AQ10: =+AI10+AM10 -> 7.1291757 | AU10: 13.95 | BA10: 8 | BB10: 42178.3 | BC10: =AL13/2-BF10 -> -1.323 | BD10: 753 | BE10: =+BE9-BE8+BE9 -> 0 | BF10: 99.573 | BG10: =INT(1+BG9) -> 6 | BH10: =VLOOKUP(BG10,TABLAS,2) -> 30889.1 | BI10: =VLOOKUP(BG10,TABLAS,3) -> -4.503 | BJ10: =VLOOKUP(BG9-0.5+1,TABLAS,4) -> 678.4 | BK10: =VLOOKUP(BG9+1.5,TABLAS,4) -> 713
BA11: 9 | BB11: 47982.5 | BC11: =AL13/2-BF11 -> 0.546 | BD11: 798.4 | BE11: =+BE10-BE9+BE10 -> 0 | BF11: 97.704
A12: A.Trim | E12: T.Trim | I12: S.G. | M12: LPP | R12: MMM | Z12: A.Trim | AD12: T.Trim | AH12: S.G. | AL12: LPP | AQ12: MMM | BA12: 10 | BB12: 53901.1 | BC12: =AL13/2-BF12 -> 2.485 | BD12: 848.2 | BE12: =+BE11-BE10+BE11 -> 0 | BF12: 95.765 | BG12: DISP | BH12: TPC | BI12: LCF | BJ12: MTC+50 | BK12: MTC-50
A13: =+J10-J8 -> 0.76 | E13: =+R10-R8 -> 0.83397554 | I13: 1.019 | M13: 196.5 | R13: =(6*R9+R8+R10)/8 -> 11.796463 | Z13: =+AI10-AI8 -> 2.3 | AD13: =+AQ10-AQ8 -> 2.5238733 | AH13: 1.019 | AL13: =+M13 -> 196.5 | AQ13: =(6*AQ9+AQ8+AQ10)/8 -> 5.7819932 | BA13: 11 | BB13: 59939.7 | BC13: =AL13/2-BF13 -> 4.085 | BD13: 891.5 | BE13: =+BE12-BE11+BE12 -> 0 | BF13: 94.165 | BG13: =(BH5-BH4*2+BH3)*BG15/3 -> 4.6609979 | BH13: =(BH5-BH4*2+BH3)*BH15/3 -> 4.4319979 | BI13: =(BI5-BI4*2+BI3)*BI15/3 -> -0.066963681 | BJ13: =(BK5-BK4*2+BK3)*BJ15/3 -> -0.65221855 | BK13: =(BJ5-BJ4*2+BJ3)*BK15/3 -> -2.5396995
BA14: 12 | BB14: 66047 | BC14: =AL13/2-BF14 -> 4.698 | BD14: 909.1 | BE14: =+BE13-BE12+BE13 -> 0 | BF14: 93.552 | BG14: =+BG4-INT(BG4) -> 0.79646298 | BH14: =+BG4+0.01-INT(BG4) -> 0.80646298 | BI14: =+BG4-INT(BG4) -> 0.79646298 | BJ14: =+BG4+0.5-INT(BG4+0.5) -> 0.29646298 | BK14: =+BG4-0.5-INT(BG4-0.5) -> 0.29646298
A15: LCF | E15: TPC | I15: MTC+50 | Q15: TPC - P | U15: TPC - S | Z15: LCF | AD15: TPC | AH15: MTC+50 | AL15: MTC-50 | AP15: TPC - P | AT15: TPC - S | BA15: 13 | BB15: 72190.4 | BC15: =AL13/2-BF15 -> 4.945 | BD15: 920.1 | BE15: =+BE14-BE13+BE14 -> 0 | BF15: 93.305 | BG15: =IF(BG14>0.5,1-BG14,BG14) -> 0.20353702 | BH15: =IF(BH14>0.5,1-BH14,BH14) -> 0.19353702 | BI15: =IF(BI14>0.5,1-BI14,BI14) -> 0.20353702 | BJ15: =IF(BJ14>0.5,1-BJ14,BJ14) -> 0.29646298 | BK15: =IF(BK14>0.5,1-BK14,BK14) -> 0.29646298
A16: =BJ28 -> 1.5318167 | E16: =BI28 -> 59.643231 | I16: =BH32 -> 853.45805 | M16: =BJ32 -> 834.17794 | Z16: =BJ37 -> -6.1080068 | AD16: =BI37 -> 55.118545 | AH16: =BH41 -> 683.46501 | AL16: =BJ41 -> 657.69151 | BA16: 14 | BB16: 78359.4 | BC16: =AL13/2-BF16 -> 4.968 | BD16: 928.4 | BE16: =+BE15-BE14+BE15 -> 0 | BF16: 93.282 | BH16: =((BH5-BH4)*BH14+BH4-BH13+0.5) -> 64861.079
BA17: 15 | BB17: 84548.1 | BC17: =AL13/2-BF17 -> 4.819 | BD17: 935.2 | BE17: =+BE16-BE15+BE16 -> 0 | BF17: 93.431 | BG17: =((BH5-BH4)*BG14+BH4-BG13+0.5) -> 64799.777 | BH17: =+BH16-BG17 -> 61.302 | BI17: =((BI5-BI4)*BI14+BI4-BI13) -> 4.6401955 | BJ17: =((BK5-BK4)*BJ14+BK4-BJ13) -> 913.01331 | BK17: =((BJ5-BJ4)*BK14+BJ4-BK13) -> 899.25745
A18: BALLAST | G18: 120.41 | M18: =BH28 -> 64634.384 | S18: DISPLACEMENT | AG18: =BH37 -> 30022.373 | AM18: BALLAST | AS18: =Deductions!AI42 -> 16346.655 | BA18: 16 | BB18: =+BB17-BB16+BB17 -> 90736.8 | BC18: =+BC17-BC16+BC17 -> 4.67 | BD18: =+BD17-BD16+BD17 -> 942 | BE18: =+BE17-BE16+BE17 -> 0 | BG18: DISP | BH18: TPC | BI18: LCF | BJ18: MTC+50 | BK18: MTC-50
A19: F.WATER | G19: 144 | M19: =ROUND(IF($S$19="Y",(((R13*100)-TRUNC(R13*100))*E16),0),2) -> 0 | S19: N | T19: DECIMAL CORRECTION | AG19: =ROUND(IF($S$19="Y",(((AQ13*100)-TRUNC(AQ13*100))*AD16),0),2) -> 0 | AM19: F.WATER | AS19: 219 | BA19: 17 | BB19: =+BB18-BB17+BB18 -> 96925.5 | BC19: =+BC18-BC17+BC18 -> 4.521 | BD19: =+BD18-BD17+BD18 -> 948.8 | BE19: =+BE18-BE17+BE18 -> 0 | BG19: =(BH10-BH9*2+BH8)*BG21/3 -> 7.5793692 | BH19: =(BH10-BH9*2+BH8)*BH21/3 -> 7.2317026 | BI19: =(BI10-BI9*2+BI8)*BI21/3 -> 0.013807096 | BJ19: =(BK10-BK9*2+BK8)*BJ21/3 -> 0.16919593 | BK19: =(BJ10-BJ9*2+BJ8)*BK21/3 -> 0.018799548
A20: FUEL OIL | G20: 1496.05 | M20: =+M19+M18 -> 64634.384 | S20: DRAFT DISPLACEMENT | AG20: =+AG19+AG18 -> 30022.373 | AM20: FUEL OIL | AS20: 1478.041 | BA20: 18 | BB20: =+BB19-BB18+BB19 -> 103114.2 | BC20: =+BC19-BC18+BC19 -> 4.372 | BD20: =+BD19-BD18+BD19 -> 955.6 | BE20: =+BE19-BE18+BE19 -> 0 | BG20: =+BG9-INT(BG9) -> 0.78199321 | BH20: =+BG9+0.01-INT(BG9) -> 0.79199321 | BI20: =+BG9-INT(BG9) -> 0.78199321 | BJ20: =+BG9+0.5-INT(BG9+0.5) -> 0.28199321 | BK20: =+BG9-0.5-INT(BG9-0.5) -> 0.28199321
A21: DIESEL OIL | G21: 156.43 | M21: =IF($M$18=0,0,(100*A16*E16*E13/M13)) -> 38.775617 | S21: TRIM CORRECTION "A" | AG21: =IF($AG$18=0,0,(100*Z16*AD16*AD13/AL13)) -> -432.4165 | AM21: DIESEL OIL | AS21: 156.03 | BG21: =IF(BG20>0.5,1-BG20,BG20) -> 0.21800679 | BH21: =IF(BH20>0.5,1-BH20,BH20) -> 0.20800679 | BI21: =IF(BI20>0.5,1-BI20,BI20) -> 0.21800679 | BJ21: =IF(BJ20>0.5,1-BJ20,BJ20) -> 0.28199321 | BK21: =IF(BK20>0.5,1-BK20,BK20) -> 0.28199321
A22: LUB OIL | M22: =IF($M$18=0,0,(50*E13*E13*(I16-M16)/M13)) -> 3.4121149 | S22: TRIM CORRECTION "B" | AG22: =IF($AG$18=0,0,(50*AD13*AD13*(AH16-AL16)/AL13)) -> 41.774942 | AM22: LUB OIL | BA22: =+BI17 -> 4.6401955 | BB22: LCF | BD22: =+BI23 -> -4.7869175 | BH22: =((BH10-BH9)*BH20+BH9-BH19+0.5) -> 29737.749
A23: SLOP | G23: 0 | M23: =+M21+M22 -> 42.187732 | S23: TOTAL TRIM CORRECTIONS | AG23: =+AG21+AG22 -> -390.64156 | AM23: SLOP | AS23: 0 | BA23: =+BH17 -> 61.302 | BB23: TPC | BD23: =+BH23 -> 55.375667 | BG23: =((BH10-BH9)*BG20+BH9-BG19+0.5) -> 29682.373 | BH23: =+BH22-BG23 -> 55.375667 | BI23: =((BI10-BI9)*BI20+BI9-BI19) -> -4.7869175 | BJ23: =((BK10-BK9)*BJ20+BK9-BJ19) -> 687.98777 | BK23: =((BJ10-BJ9)*BK20+BJ9-BK19) -> 654.83058
A24: S, POOL | G24: 0 | M24: =ROUND(6*(Q16-U16)*(A9-E9),2) -> 0 | S24: LIST CORRECTION | AG24: =ROUND(6*(AP16-AT16)*(Z9-AD9),2) -> 0 | AM24: S, POOL | AS24: 0 | BA24: =+BJ17 -> 913.01331 | BB24: MTC+50 | BD24: =+BJ23 -> 687.98777
A25: OTHERS | M25: =+M20+M23+M24 -> 64676.572 | S25: CORRECTED DISPLACEMENT | AG25: =+AG20+AG23+AG24 -> 29631.731 | AM25: OTHERS | BA25: =+BK17 -> 899.25745 | BB25: MTC-50 | BD25: =+BK23 -> 654.83058
A26: DEDUCTIONS | G26: =SUM(G18:K25) -> 1916.89 | M26: =((I13-1.025)*M25)/1.025 -> -378.59457 | S26: DENSITY CORRECTION | AG26: =((AH13-1.025)*AG25)/1.025 -> -173.45404 | AM26: DEDUCTIONS | AS26: =SUM(AS18:AW25) -> 18199.726 | BA26: =+BG17 -> 64799.777 | BB26: DRAFT DISPLACEMENT | BD26: =+BG23 -> 29682.373 | BG26: DRAFT | BH26: DISP | BI26: TPC | BJ26: LCF | BK26: LCB
A27: CONDITIONS | I27: GOOD | J27: REG | K27: BAD | M27: =+M25+M26 -> 64297.977 | S27: TRUE DISPLACEMENT | AG27: =+AG25+AG26 -> 29458.277 | BA27: =100*BA22*BA23*E13/M13 -> 120.72624 | BB27: TRIM CORRECTION "A" | BD27: =100*BD22*BD23*AD13/M13 -> -340.47083 | BG27: 11.75 | BH27: 64357 | BI27: 59.62 | BJ27: 1.49 | BK27: =M13 -> 196.5
M28: =+G26 -> 1916.89 | S28: TOTAL DEDUCTIONS | AG28: =+AS26 -> 18199.726 | BA28: =50*E13*E13*(BA24-BA25)/M13 -> 2.434456 | BB28: TRIM CORRECTION "B" | BD28: =50*Z13*AD13*(BD24-BD25)/M13 -> 48.975692 | BG28: =+BG4 -> 11.796463 | BH28: =BH27+(BG28-BG27)*(BH29-BH27)/(BG29-BG27) -> 64634.384 | BI28: =BI27+(BG28-BG27)*(BI29-BI27)/(BG29-BG27) -> 59.643231 | BJ28: =BJ27+(BG28-BG27)*(BJ29-BJ27)/(BG29-BG27) -> 1.5318167 | BK28: =BK27/2 -> 98.25
M29: 10787 | S29: LIGHT SHIP | AG29: =IF(AG18=0,0,M29) -> 10787 | AN29: =General!H11 -> Velez Rene Boy Enriquez | BA29: =+BA27+BA28 -> 123.1607 | BB29: TOTAL TRIM CORRECTIONS | BD29: =+BD27+BD28 -> -291.49514 | BG29: 11.85 | BH29: 64954 | BI29: 59.67 | BJ29: 1.58 | BK29: 90.49
A30: SOUNDING PIPES | I30: X | M30: 300 | S30: HISTORIC CONSTANT | AR30: CHIEF OFFICER | BB30: LIST CORRECTION | BG30: 42452.2 | BH30: MTC +50 | BI30: DRAFT - | BJ30: MTC - 50 | BK30: =BK28-BK29 -> 7.76
A31: DRAFT MARKS | I31: X | M31: =IF(M30=0,(M27-M28-M29),0) -> 0 | S31: CONSTANT "K" | AG31: =IF(AG18=0,0,(IF(M30=0,M31,AG27-AG28-AG29))) -> 471.55072 | BA31: =+BA26+BA29+BA30 -> 64922.938 | BB31: CORRECTED DISP. | BD31: =+BD26+BD29+BD30 -> 29390.878 | BG31: =BG27+0.5 -> 12.25 | BH31: 852.71 | BI31: =+BG31-1 -> 11.25 | BJ31: 833.1
A32: SWELL INITIAL | J32: X | M32: =+M27-M28 -> 62381.087 | S32: INITIAL NET LIGHT DISPLACEMENT | AG32: =IF(AG18=0,0,M32) -> 62381.087 | AN32: =General!H10 -> Sunday Val m. Sobremonte | BA32: =+BA31-M25 -> 246.36633 | BB32: DIFFERENCE | BD32: =+BD31-AG25 -> -240.85334 | BG32: =+BG28+0.5 -> 12.296463 | BH32: =BH31+(BG32-BG31)*(BH33-BH31)/(BG33-BG31) -> 853.45805 | BI32: =+BG32-1 -> 11.296463 | BJ32: =BJ31+(BI32-BI31)*(BJ33-BJ31)/(BI33-BI31) -> 834.17794
A33: SWELL FINAL | J33: X | S33: FINAL NET LIGHT DISPLACEMENT | AG33: =+AG27-AG28 -> 11258.551 | AR33: MASTER | BG33: =BG29+0.5 -> 12.35 | BH33: 854.32 | BI33: =+BG33-1 -> 11.35 | BJ33: 835.42
A34: HYDROSTATIC TB. | I34: X | M34: =IF(M30=0,M31,M27-M28-M29-M30) -> 51294.087 | S34: INIT FIGURE | Y34: SURVEY FIGURE | AG34: =ABS(+AG32-AG33) -> 51122.536 | BB34: INITIAL
A35: DISTANCE TO MARKS | I35: X | M35: 51045.423 | S35: B/L FIGURE | AG35: 51045.42 | AN35: =General!AB10 -> MANFRED BOLAÑOS | BA35: =+A8 -> 11.43 | BB35: =+BB36 -> 28.3 | BC35: =BA35+BB35*((BC36-BA36)/BB36) -> 11.44 | BG35: DRAFT | BH35: DISP | BI35: TPC | BJ35: LCF
A36: BALLAST TABLES | I36: X | M36: =+M34-M35 -> 248.66413 | S36: DIFFERENCE | AG36: =+AG34-AG35 -> 77.116413 | AR36: MSL SURVEYOR | BA36: =+A9 -> 11.78 | BB36: =+General!M21 -> 28.3 | BC36: =+E9 -> 11.79 | BG36: 5.5 | BH36: 28470 | BI36: 54.9 | BJ36: -6.39
A37: REMARK: Swell Condition, Initial ( 0,10 to 0.20 Mtr) / Final Draft ( 0,10 to 0,20 Mtr) | BA37: =+A10 -> 12.19 | BB37: =+BB36 -> 28.3 | BC37: =BA37+BB37*((BC36-BA36)/BB36) -> 12.2 | BG37: =+AQ13 -> 5.7819932 | BH37: =BH36+(BG37-BG36)*(BH38-BH36)/(BG38-BG36) -> 30022.373 | BI37: =BI36+(BG37-BG36)*(BI38-BI36)/(BG38-BG36) -> 55.118545 | BJ37: =BJ36+(BG37-BG36)*(BJ38-BJ36)/(BG38-BG36) -> -6.1080068
BA38: LIST = | BB38: =ROUND((ATAN((BA36-BC36)/BB36)*180/PI()),2) -> -0.02 | BC38: º | BG38: 5.9 | BH38: 30672 | BI38: 55.21 | BJ38: -5.99
BA39: =BC39+BB39*((BA40-BC40)/BB40) -> 11.43 | BB39: =+BB40 -> 28.3 | BC39: =+E8 -> 11.44 | BG39: DRAFT + | BH39: MTC +50 | BI39: DRAFT - | BJ39: MTC - 50
BA40: =+A9 -> 11.78 | BB40: =+BB36 -> 28.3 | BC40: =+E9 -> 11.79 | BG40: =BG36+0.5 -> 6 | BH40: 675.4 | BI40: =+BG40-1 -> 5 | BJ40: 651.96
...

Sheet E
A1: U.N. , ECE - DRAUGHT SURVEY CODE
AI2: FORM "E"
A3: DRAUGHT SURVEY REPORT OF CARGO IN BULK | Z3: =+A!Z3 -> X | AA3: LOADED
Z4: =+A!Z4 -> 0 | AA4: UNLOADED
B5: Corporate identification:
A6: =A!B6 -> MSL Marine Surveyors And Logistics
B7: Vessel M/V : | Z7: Survey no:
F8: =+A!G12 -> MV SANTA CAROLINA | AC8: =+A!AG12 -> 2207-1407-2026
A9: CARGO STATEMENT
Y11: Metric Tonnes
A14: Starting Displacement Corrected | Y14: =+Draft!M32 -> 62381.087
A16: Finishing Displacement Corrected | Y16: =+Draft!AG33 -> 11258.551
AW17: According Remark
A18: Difference in Displacement = TOTAL CARGO IN BULK IS: | Y18: =ROUND(+Draft!AG34,2) -> 51122.54 | AW18: Form "A"
B20: OBSERVATIONS: Shore scale quantity (if available) M.T.
B21: Note on any unusual situatonts, exception/s from required Uniform Code standard, specific identification
B22: (source, drawing no., date, title. certifying authority) of each ships document used in translating recorded
B23: measurements lrvto weights and, when applicable, reasons for surveyors refusal or impossibility to perform
B24: the survey:
X27: Metric Tonnes
A28: Corrected light displacement = | X28: =IF(Y16=0,0,IF(Y14=0,0,IF(Draft!M27>Draft!AG27,Draft!M27,Draft!AG27))) -> 64297.977
A29: Deductables = | X29: =IF(X28=0,0,IF(Draft!M27>Draft!AG27,Draft!G26,Draft!AS26)) -> 1916.89
A30: Lightship = | X30: =IF(X29=0,0,+Draft!AG29) -> 10787
A31: Constant = | X31: =IF(X30=0,0,+Draft!AG31) -> 471.55072
A32: Mean of previous constants =
B35: I certify that the constant calculated from this draught survey has been entered into the ship's 'Constant Certificate'
B38: In my judgement the weather conditions, the sea conditions, and the conditions of the ship at the times the
B39: draught surveys were conducted, were within acceptable limits and did not adversely affect the accuracy of
B40: this survey. This Bona Fide report consisting of 4 pages, including this page, all duly initialled or signed
B41: is issued without prejudice and is for the benefit of whom It may concern.
B45: Name at surveying firm
B47: By: | AB47: =A!B6 -> MSL Marine Surveyors And Logistics
B48: (Signature of Surveyor/s)
B50: Name/s in print | H50: =CONCATENATE(AB54," - ",AB56," - ",General!AB10) -> Sunday Val m. Sobremonte - Velez Rene Boy Enriquez - MANFRED BOLAÑOS
A51: I have participated in all stages of this draught survey, and agree with the results obtained. I acknowledge receipt of the ship's copy.
B53: Signed: | M53: Rank: | T53: Name in print:
M54: MASTER | AB54: =+General!H10 -> Sunday Val m. Sobremonte
M56: CHIEF OFFICER | AB56: =+General!H11 -> Velez Rene Boy Enriquez

Sheet D1
A1: U.N. , ECE - DRAUGHT SURVEY CODE
AI2: FORM "D1"
A3: DRAUGHT SURVEY REPORT OF CARGO IN BULK | Z3: =+A!Z3 -> X | AA3: LOADED
Z4: =+A!Z4 -> 0 | AA4: UNLOADED
B5: Corporate identification:
A6: =A!B6 -> MSL Marine Surveyors And Logistics
B7: Vessel M/V : | Z7: Survey no:
F8: =+A!G12 -> MV SANTA CAROLINA | AC8: =+A!AG12 -> 2207-1407-2026
A9: STARTING SOUNDING: | K9: From Hours: | S9: To Hours | AB9: Date: | AJ9: Trim:
K10: =Draft!T3 -> 0.63888889 | S10: =Draft!T4 -> 0.68055556 | AB10: =+Draft!T2 -> 46217 | AJ10: =+Draft!E13 -> 0.83397554 | AN10: M
S11: Sounding
A12: Compartment Title. | I12: Maximun | N12: Sounding | S12: / ullage | X12: Volume | AD12: Density of | AJ12: Total
B13: * Tank no. | I13: height | N13: / ullage | S13: corrected for | X13: corrected | AD13: Water | AJ13: weight
B14: * Bilges | I14: meausured (*) | N14: metres | S14: trim / list | X14: for trim / list | AD14: in air | AJ14: Metric
B15: * Duct Keel | I15: metres | S15: metres | X15: m3 | AD15: Kg/m3 | AJ15: tonnes
B16: A - BALLAST
B18: =+Deductions!A11 -> FPT | I18: =+Deductions!D11 -> 0 | N18: =+Deductions!G11 -> 0.03 | X18: =+Deductions!J11 -> 2.09 | AD18: =+Deductions!M11 -> 1.021 | AJ18: =+Deductions!P11 -> 2.13389
B19: =+Deductions!A12 -> WBT 1P | I19: =+Deductions!D12 -> 0 | N19: =+Deductions!G12 -> EMPTY | X19: =+Deductions!J12 -> 3.55 | AD19: =+Deductions!M12 -> 1.021 | AJ19: =+Deductions!P12 -> 3.62455
B20: =+Deductions!A13 -> WBT 1S | I20: =+Deductions!D13 -> 0 | N20: =+Deductions!G13 -> 0.1 | X20: =+Deductions!J13 -> 28.92 | AD20: =+Deductions!M13 -> 1.021 | AJ20: =+Deductions!P13 -> 29.52732
B21: =+Deductions!A14 -> WBT 2P | I21: =+Deductions!D14 -> 0 | N21: =+Deductions!G14 -> 0.02 | X21: =+Deductions!J14 -> 12.03 | AD21: =+Deductions!M14 -> 1.021 | AJ21: =+Deductions!P14 -> 12.28263
B22: =+Deductions!A15 -> WBT 2S | I22: =+Deductions!D15 -> 0 | N22: =+Deductions!G15 -> EMPTY | X22: =+Deductions!J15 -> 5.82 | AD22: =+Deductions!M15 -> 1.021 | AJ22: =+Deductions!P15 -> 5.94222
B23: =+Deductions!A16 -> WBT 3P | I23: =+Deductions!D16 -> 0 | N23: =+Deductions!G16 -> EMPTY | X23: =+Deductions!J16 -> 6.96 | AD23: =+Deductions!M16 -> 1.021 | AJ23: =+Deductions!P16 -> 7.10616
B24: =+Deductions!A17 -> WBT 3S | I24: =+Deductions!D17 -> 0 | N24: =+Deductions!G17 -> 0.01 | X24: =+Deductions!J17 -> 6.24 | AD24: =+Deductions!M17 -> 1.021 | AJ24: =+Deductions!P17 -> 6.37104
B25: =+Deductions!A18 -> WBT 4P | I25: =+Deductions!D18 -> 0 | N25: =+Deductions!G18 -> 0.01 | X25: =+Deductions!J18 -> 4.56 | AD25: =+Deductions!M18 -> 1.021 | AJ25: =+Deductions!P18 -> 4.65576
B26: =+Deductions!A19 -> WBT 4S | I26: =+Deductions!D19 -> 0 | N26: =+Deductions!G19 -> EMPTY | X26: =+Deductions!J19 -> 4.33 | AD26: =+Deductions!M19 -> 1.021 | AJ26: =+Deductions!P19 -> 4.42093
B27: =+Deductions!A20 -> WBT 5P | I27: =+Deductions!D20 -> 0 | N27: =+Deductions!G20 -> EMPTY | X27: =+Deductions!J20 -> 7.83 | AD27: =+Deductions!M20 -> 1.021 | AJ27: =+Deductions!P20 -> 7.99443
B28: =+Deductions!A21 -> WBT 5S | I28: =+Deductions!D21 -> 0 | N28: =+Deductions!G21 -> EMPTY | X28: =+Deductions!J21 -> 7.01 | AD28: =+Deductions!M21 -> 1.021 | AJ28: =+Deductions!P21 -> 7.15721
B29: =+Deductions!A22 -> APT | I29: =+Deductions!D22 -> 0 | N29: =+Deductions!G22 -> 0.01 | X29: =+Deductions!J22 -> 0.2 | AD29: =+Deductions!M22 -> 1.021 | AJ29: =+Deductions!P22 -> 0.2042
... B44: =+Deductions!A37 -> 0 | I44: =+Deductions!D37 -> 0 | N44: =+Deductions!G37 -> 0 | X44: =+Deductions!J37 -> 0 | AD44: =+Deductions!M37 -> 0 | AJ44: =+Deductions!P37 -> 0
B45: Total A | AJ45: =+Deductions!P42 -> 120.40034
B46: B - FRESH WATER
B48: =+Deductions!A47 -> FWT P | I48: =+Deductions!D47 -> 0 | N48: =+Deductions!G47 -> GAUGE | X48: =+Deductions!J47 -> 57 | AD48: =+Deductions!M47 -> 1 | AJ48: =+Deductions!P47 -> 57
B49: =+Deductions!A48 -> DW | I49: =+Deductions!D48 -> 0 | N49: =+Deductions!G48 -> GAUGE | X49: =+Deductions!J48 -> 87 | AD49: =+Deductions!M48 -> 1 | AJ49: =+Deductions!P48 -> 87
B50: =+Deductions!A49 -> 0 | I50: =+Deductions!D49 -> 0 | N50: =+Deductions!G49 -> 0 | X50: =+Deductions!J49 -> 0 | AD50: =+Deductions!M49 -> 0 | AJ50: =+Deductions!P49 -> 0
B51: =+Deductions!A50 -> 0 | I51: =+Deductions!D50 -> 0 | N51: =+Deductions!G50 -> 0 | X51: =+Deductions!J50 -> 0 | AD51: =+Deductions!M50 -> 0 | AJ51: =+Deductions!P50 -> 0
B52: =+Deductions!A51 -> 0 | I52: =+Deductions!D51 -> 0 | N52: =+Deductions!G51 -> 0 | X52: =+Deductions!J51 -> 0 | AD52: =+Deductions!M51 -> 0 | AJ52: =+Deductions!P51 -> 0
B53: =+Deductions!A52 -> 0 | I53: =+Deductions!D52 -> 0 | N53: =+Deductions!G52 -> 0 | X53: =+Deductions!J52 -> 0 | AD53: =+Deductions!M52 -> 0 | AJ53: =+Deductions!P52 -> 0
B54: Total B | AJ54: =+Deductions!P54 -> 144 | AO54: =SUM(AO48:AO53) -> 0
AV55: (*) Statement of obstructions in sounding tube/s:
C56: =IF(Deductions!AC4="X", Deductions!AD4," ")

Sheet D2
A1: U.N. , ECE - DRAUGHT SURVEY CODE
AI2: FORM "D2"
A3: DRAUGHT SURVEY REPORT OF CARGO IN BULK | Z3: =+A!Z3 -> X | AA3: LOADED
Z4: =+A!Z4 -> 0 | AA4: UNLOADED
B5: Corporate identification:
A6: =A!B6 -> MSL Marine Surveyors And Logistics
B7: Vessel M/V : | Z7: Survey no:
F8: =+A!G12 -> MV SANTA CAROLINA | AC8: =+A!AG12 -> 2207-1407-2026
A9: FINISHING SOUNDING: | K9: From Hours: | S9: To Hours | AB9: Date: | AJ9: Trim:
K10: =Draft!AS3 -> 0.66666667 | S10: =Draft!AS4 -> 0.69444444 | AB10: =+Draft!AS2 -> 46221 | AJ10: =+Draft!AD13 -> 2.5238733 | AN10: M
S11: Sounding
A12: Compartment Title. | I12: Maximun | N12: Sounding | S12: / ullage | X12: Volume | AD12: Density of | AJ12: Total
B13: * Tank no. | I13: height | N13: / ullage | S13: corrected for | X13: corrected | AD13: Water | AJ13: weight
B14: * Bilges | I14: meausured (*) | N14: metres | S14: trim / list | X14: for trim / list | AD14: in air | AJ14: Metric
B15: * Duct Keel | I15: metres | S15: metres | X15: m3 | AD15: Kg/m3 | AJ15: tonnes
B16: A - BALLAST
B18: =+'D1'!B18:H18 -> FPT | I18: =+'D1'!I18:M18 -> 0 | N18: =+Deductions!Z11 -> 9.8 | X18: =+Deductions!AC11 -> 1156.55 | AD18: =+Deductions!AF11 -> 1.019 | AJ18: =+Deductions!AI11 -> 1178.5244
B19: =+'D1'!B19:H19 -> WBT 1P | I19: =+'D1'!I19:M19 -> 0 | N19: =+Deductions!Z12 -> 18.57 | X19: =+Deductions!AC12 -> 1321.27 | AD19: =+Deductions!AF12 -> 1.019 | AJ19: =+Deductions!AI12 -> 1346.3741
B20: =+'D1'!B20:H20 -> WBT 1S | I20: =+'D1'!I20:M20 -> 0 | N20: =+Deductions!Z13 -> 18.66 | X20: =+Deductions!AC13 -> 1333.57 | AD20: =+Deductions!AF13 -> 1.019 | AJ20: =+Deductions!AI13 -> 1358.9078
B21: =+'D1'!B21:H21 -> WBT 2P | I21: =+'D1'!I21:M21 -> 0 | N21: =+Deductions!Z14 -> 18.33 | X21: =+Deductions!AC14 -> 1766.19 | AD21: =+Deductions!AF14 -> 1.019 | AJ21: =+Deductions!AI14 -> 1799.7476
B22: =+'D1'!B22:H22 -> WBT 2S | I22: =+'D1'!I22:M22 -> 0 | N22: =+Deductions!Z15 -> 18.36 | X22: =+Deductions!AC15 -> 1772.66 | AD22: =+Deductions!AF15 -> 1.019 | AJ22: =+Deductions!AI15 -> 1806.3405
B23: =+'D1'!B23:H23 -> WBT 3P | I23: =+'D1'!I23:M23 -> 0 | N23: =+Deductions!Z16 -> 18.62 | X23: =+Deductions!AC16 -> 1739.57 | AD23: =+Deductions!AF16 -> 1.019 | AJ23: =+Deductions!AI16 -> 1772.6218
B24: =+'D1'!B24:H24 -> WBT 3S | I24: =+'D1'!I24:M24 -> 0 | N24: =+Deductions!Z17 -> 18.5 | X24: =+Deductions!AC17 -> 1715.19 | AD24: =+Deductions!AF17 -> 1.019 | AJ24: =+Deductions!AI17 -> 1747.7786
B25: =+'D1'!B25:H25 -> WBT 4P | I25: =+'D1'!I25:M25 -> 0 | N25: =+Deductions!Z18 -> 18.5 | X25: =+Deductions!AC18 -> 1297.73 | AD25: =+Deductions!AF18 -> 1.019 | AJ25: =+Deductions!AI18 -> 1322.3869
B26: =+'D1'!B26:H26 -> WBT 4S | I26: =+'D1'!I26:M26 -> 0 | N26: =+Deductions!Z19 -> 18.76 | X26: =+Deductions!AC19 -> 1346.46 | AD26: =+Deductions!AF19 -> 1.019 | AJ26: =+Deductions!AI19 -> 1372.0427
B27: =+'D1'!B27:H27 -> WBT 5P | I27: =+'D1'!I27:M27 -> 0 | N27: =+Deductions!Z20 -> 18.26 | X27: =+Deductions!AC20 -> 1001.4 | AD27: =+Deductions!AF20 -> 1.019 | AJ27: =+Deductions!AI20 -> 1020.4266
B28: =+'D1'!B28:H28 -> WBT 5S | I28: =+'D1'!I28:M28 -> 0 | N28: =+Deductions!Z21 -> 18.54 | X28: =+Deductions!AC21 -> 1052.34 | AD28: =+Deductions!AF21 -> 1.019 | AJ28: =+Deductions!AI21 -> 1072.3345
B29: =+'D1'!B29:H29 -> APT | I29: =+'D1'!I29:M29 -> 0 | N29: =+Deductions!Z22 -> 6.91 | X29: =+Deductions!AC22 -> 485.98 | AD29: =+Deductions!AF22 -> 1.019 | AJ29: =+Deductions!AI22 -> 495.21362
... B44: =+'D1'!B44:H44 -> 0 | I44: =+'D1'!I44:M44 -> 0 | N44: =+Deductions!Z37 -> 0 | X44: =+Deductions!AC37 -> 0 | AD44: =+Deductions!AF37 -> 0 | AJ44: =+Deductions!AI37 -> 0
B45: Total A | AJ45: =+Deductions!AI42 -> 16346.655
B46: B - FRESH WATER
B48: =+'D1'!B48:H48 -> FWT P | I48: =+'D1'!I48:M48 -> 0 | N48: =+Deductions!Z47 -> GAUGE | X48: =+Deductions!AC47 -> 133 | AD48: =+Deductions!AF47 -> 1 | AJ48: =+Deductions!AI47 -> 133
B49: =+'D1'!B49:H49 -> DW | I49: =+'D1'!I49:M49 -> 0 | N49: =+Deductions!Z48 -> GAUGE | X49: =+Deductions!AC48 -> 86 | AD49: =+Deductions!AF48 -> 1 | AJ49: =+Deductions!AI48 -> 86
B50: =+'D1'!B50:H50 -> 0 | I50: =+'D1'!I50:M50 -> 0 | N50: =+Deductions!Z49 -> 0 | X50: =+Deductions!AC49 -> 0 | AD50: =+Deductions!AF49 -> 0 | AJ50: =+Deductions!AI49 -> 0
B51: =+'D1'!B51:H51 -> 0 | I51: =+'D1'!I51:M51 -> 0 | N51: =+Deductions!Z50 -> 0 | X51: =+Deductions!AC50 -> 0 | AD51: =+Deductions!AF50 -> 0 | AJ51: =+Deductions!AI50 -> 0
B52: =+'D1'!B52:H52 -> 0 | I52: =+'D1'!I52:M52 -> 0 | N52: =+Deductions!Z51 -> 0 | X52: =+Deductions!AC51 -> 0 | AD52: =+Deductions!AF51 -> 0 | AJ52: =+Deductions!AI51 -> 0
B53: =+'D1'!B53:H53 -> 0 | I53: =+'D1'!I53:M53 -> 0 | N53: =+Deductions!Z52 -> 0 | X53: =+Deductions!AC52 -> 0 | AD53: =+Deductions!AF52 -> 0 | AJ53: =+Deductions!AI52 -> 0
B54: Total B | AJ54: =+Deductions!AI54 -> 219 | AO54: =SUM(AO48:AO53) -> 0 | AV54: (*) Statement of obstructions in sounding tube/s:
C56: =IF(Deductions!AC4="X", Deductions!AD4," ")

Sheet Hoja1

Sheet D3
A1: U.N. , ECE - DRAUGHT SURVEY CODE
AI2: FORM "D3"
A3: DRAUGHT SURVEY REPORT OF CARGO IN BULK | Z3: =+A!Z3 -> X | AA3: LOADED
Z4: =+A!Z4 -> 0 | AA4: UNLOADED
B5: Corporate identification:
A6: =A!B6 -> MSL Marine Surveyors And Logistics
B7: Vessel M/V : | Z7: Survey no:
F8: =+A!G12 -> MV SANTA CAROLINA | AC8: =+A!AG12 -> 2207-1407-2026
A9: SOUNDINGS
A11: Compartment | J11: STARTING SURVEY | Z11: FINISHING SURVEY
A12: Title, | F12: Total | J12: Sounding | M12: Temp | O12: Actual | R12: Actual | V12: Weight | Z12: Sounding | AC12: Temp | AE12: Actual | AH12: Actual | AL12: Weight
A13: Tank no. | F13: sounded | J13: Ullage | O13: Density | R13: Volume | V13: Metric | Z13: Ullage | AE13: Density | AH13: Volume | AL13: Metric
A14: Slop t. | F14: depth m. | J14: metres | M14: º C | O14: Kg/m3 | R14: m3 | V14: Tonnes | Z14: metres | AC14: º C | AE14: Kg/m3 | AH14: m3 | AL14: Tonnes
B15: C - FUEL OIL
V17: =ROUND(R17*(O17-(0.00063*(M17-15))),2) -> 0 | AL17: =ROUND(AH17*(AE17-(0.00063*(AC17-15))),2) -> 0
V18: =ROUND(R18*(O18-(0.00063*(M18-15))),2) -> 0 | AL18: =ROUND(AH18*(AE18-(0.00063*(AC18-15))),2) -> 0
V19: =ROUND(R19*(O19-(0.00063*(M19-15))),2) -> 0 | AL19: =ROUND(AH19*(AE19-(0.00063*(AC19-15))),2) -> 0
V20: =ROUND(R20*(O20-(0.00063*(M20-15))),2) -> 0 | AL20: =ROUND(AH20*(AE20-(0.00063*(AC20-15))),2) -> 0
V21: =ROUND(R21*(O21-(0.00063*(M21-15))),2) -> 0 | AL21: =ROUND(AH21*(AE21-(0.00063*(AC21-15))),2) -> 0
V22: =ROUND(R22*(O22-(0.00063*(M22-15))),2) -> 0 | AL22: =ROUND(AH22*(AE22-(0.00063*(AC22-15))),2) -> 0
V23: =ROUND(R23*(O23-(0.00063*(M23-15))),2) -> 0 | AL23: =ROUND(AH23*(AE23-(0.00063*(AC23-15))),2) -> 0
V24: =ROUND(R24*(O24-(0.00063*(M24-15))),2) -> 0 | AL24: =ROUND(AH24*(AE24-(0.00063*(AC24-15))),2) -> 0
V25: =ROUND(R25*(O25-(0.00063*(M25-15))),2) -> 0 | AL25: =ROUND(AH25*(AE25-(0.00063*(AC25-15))),2) -> 0
V26: =ROUND(R26*(O26-(0.00063*(M26-15))),2) -> 0 | AL26: =ROUND(AH26*(AE26-(0.00063*(AC26-15))),2) -> 0
V27: =ROUND(R27*(O27-(0.00063*(M27-15))),2) -> 0 | AL27: =ROUND(AH27*(AE27-(0.00063*(AC27-15))),2) -> 0
V28: =ROUND(R28*(O28-(0.00063*(M28-15))),2) -> 0 | AL28: =ROUND(AH28*(AE28-(0.00063*(AC28-15))),2) -> 0
... V30: =ROUND(R30*(O30-(0.00063*(M30-15))),2) -> 0 | AL30: =ROUND(AH30*(AE30-(0.00063*(AC30-15))),2) -> 0
A31: Total C | V31: =IF(Draft!G20=0,SUM(V17:Y30),Draft!G20) -> 1496.05 | AL31: =IF(Draft!AS20=0,SUM(AL17:AO30),Draft!AS20) -> 1478.041
B32: D - DIESEL OIL
V34: =ROUND(R34*(O34-(0.00065*(M34-15))),2) -> 0 | AL34: =ROUND(AH34*(AE34-(0.00065*(AC34-15))),2) -> 0
V35: =ROUND(R35*(O35-(0.00065*(M35-15))),2) -> 0 | AL35: =ROUND(AH35*(AE35-(0.00065*(AC35-15))),2) -> 0
V36: =ROUND(R36*(O36-(0.00065*(M36-15))),2) -> 0 | AL36: =ROUND(AH36*(AE36-(0.00065*(AC36-15))),2) -> 0
V37: =ROUND(R37*(O37-(0.00065*(M37-15))),2) -> 0 | AL37: =ROUND(AH37*(AE37-(0.00065*(AC37-15))),2) -> 0
V38: =ROUND(R38*(O38-(0.00065*(M38-15))),2) -> 0 | AL38: =ROUND(AH38*(AE38-(0.00065*(AC38-15))),2) -> 0
V39: =ROUND(R39*(O39-(0.00065*(M39-15))),2) -> 0 | AL39: =ROUND(AH39*(AE39-(0.00065*(AC39-15))),2) -> 0
A40: Total D | V40: =IF(Draft!G21=0,SUM(V34:Y39),Draft!G21) -> 156.43 | AL40: =IF(Draft!AS21=0,SUM(AL34:AO39),Draft!AS21) -> 156.03
A42: SUMMARY OF DEDUCTIBLES
N43: STARTING SURVEY | Z43: FINISHING SURVEY
N44: metric tonnes | Z44: metric tonnes
A45: Ballast water | O45: =+Draft!G18 -> 120.41 | AA45: =+Draft!AS18 -> 16346.655
...

Sheet Deductions
A1: ,
A2: DATE | D2: =+Draft!T2 -> 46217 | H2: FROM | K2: =Draft!T3 -> 0.63888889 | N2: TO | P2: =Draft!T4 -> 0.68055556 | T2: DATE | W2: =+Draft!AS2 -> 46221 | AA2: FROM | AD2: =Draft!AS3 -> 0.66666667 | AG2: TO | AI2: =Draft!AS4 -> 0.69444444
A4: SI HAY DIFERENCIAS ENTRE LAS DISTANCIAS DE LAS SONDAS DE DOS TANQUES | AD4: *** POSIBLY OBSTRUCTION
A5: GEMELOS (EJ. TST 2 P Y TST 2S) SE DEBE CLOCAR UN ASTERISCO EN EL
A6: NOMBRE DEL TANQUE, Y MARCAR CON "X" LA CASILLA DE POSIBLE OBSTRUCCION
A8: Tank | D8: Height | G8: Sounding | J8: Volume | M8: Density | P8: Total | T8: Tank | W8: Height | Z8: Sounding | AC8: Volume | AF8: Density | AI8: Total
A10: INITIAL BALLAST | T10: FINAL BALLAST
A11: FPT | D11: 0 | G11: 0.03 | J11: 2.09 | M11: 1.021 | P11: =+M11*J11 -> 2.13389 | T11: =+A11 -> FPT | Z11: 9.8 | AC11: 1156.55 | AF11: 1.019 | AI11: =+AF11*AC11 -> 1178.5244 | AR11: =AP15/AR13 -> 0.5759472
A12: WBT 1P | D12: 0 | G12: EMPTY | J12: 3.55 | M12: 1.021 | P12: =+M12*J12 -> 3.62455 | T12: =+A12 -> WBT 1P | Z12: 18.57 | AC12: 1321.27 | AF12: 1.019 | AI12: =+AF12*AC12 -> 1346.3741 | AN12: SOUNDING | AP12: TRIM | AR12: CORRECCION SONDA M.M
A13: WBT 1S | D13: 0 | G13: 0.1 | J13: 28.92 | M13: 1.021 | P13: =+M13*J13 -> 29.52732 | T13: =+A13 -> WBT 1S | Z13: 18.66 | AC13: 1333.57 | AF13: 1.019 | AI13: =+AF13*AC13 -> 1358.9078 | AO13: 2 | AP13: 2.26 | AQ13: 3 | AR13: 1000
A14: WBT 2P | D14: 0 | G14: 0.02 | J14: 12.03 | M14: 1.021 | P14: =+M14*J14 -> 12.28263 | T14: =+A14 -> WBT 2P | Z14: 18.33 | AC14: 1766.19 | AF14: 1.019 | AI14: =+AF14*AC14 -> 1799.7476 | AN14: 6.1 | AO14: 573 | AQ14: 574.5 | AR14: =AN15+AR11 -> 6.7059472 | AS14: +
A15: WBT 2S | D15: 0 | G15: EMPTY | J15: 5.82 | M15: 1.021 | P15: =+M15*J15 -> 5.94222 | T15: =+A15 -> WBT 2S | Z15: 18.36 | AC15: 1772.66 | AF15: 1.019 | AI15: =+AF15*AC15 -> 1806.3405 | AN15: 6.13 | AO15: =((AO14-AO16)/(AN14-AN16))*(AN15-AN16)+AO16 -> 575.76 | AP15: =AO15-(AO15-AQ15)/(AQ13-AO13)*(AP13-AO13) -> 575.9472 | AQ15: =((AQ14-AQ16)/(AN14-AN16))*(AN15-AN16)+AQ16 -> 576.48 | AR15: =AN15-AR11 -> 5.5540528 | AS15: -
A16: WBT 3P | D16: 0 | G16: EMPTY | J16: 6.96 | M16: 1.021 | P16: =+M16*J16 -> 7.10616 | T16: =+A16 -> WBT 3P | Z16: 18.62 | AC16: 1739.57 | AF16: 1.019 | AI16: =+AF16*AC16 -> 1772.6218 | AN16: 6.15 | AO16: 577.6 | AQ16: 577.8 | AU16: =AN15-0.0339 -> 6.0961
A17: WBT 3S | D17: 0 | G17: 0.01 | J17: 6.24 | M17: 1.021 | P17: =+M17*J17 -> 6.37104 | T17: =+A17 -> WBT 3S | Z17: 18.5 | AC17: 1715.19 | AF17: 1.019 | AI17: =+AF17*AC17 -> 1747.7786
A18: WBT 4P | D18: 0 | G18: 0.01 | J18: 4.56 | M18: 1.021 | P18: =+M18*J18 -> 4.65576 | T18: =+A18 -> WBT 4P | Z18: 18.5 | AC18: 1297.73 | AF18: 1.019 | AI18: =+AF18*AC18 -> 1322.3869 | AN18: SOUNDING | AP18: HEEL | AR18: =AP21/AR20 -> 0.001104 | AU18: 0.064
A19: WBT 4S | D19: 0 | G19: EMPTY | J19: 4.33 | M19: 1.021 | P19: =+M19*J19 -> 4.42093 | T19: =+A19 -> WBT 4S | Z19: 18.76 | AC19: 1346.46 | AF19: 1.019 | AI19: =+AF19*AC19 -> 1372.0427 | AO19: 1 | AP19: =AP13 -> 2.26 | AQ19: 2 | AR19: CORRECCION SONDA M.M | AU19: =AN15-AU18 -> 6.066
A20: WBT 5P | D20: 0 | G20: EMPTY | J20: 7.83 | M20: 1.021 | P20: =+M20*J20 -> 7.99443 | T20: =+A20 -> WBT 5P | Z20: 18.26 | AC20: 1001.4 | AF20: 1.019 | AI20: =+AF20*AC20 -> 1020.4266 | AN20: 0.8 | AO20: 0 | AQ20: 0 | AR20: 1000
A21: WBT 5S | D21: 0 | G21: EMPTY | J21: 7.01 | M21: 1.021 | P21: =+M21*J21 -> 7.15721 | T21: =+A21 -> WBT 5S | Z21: 18.54 | AC21: 1052.34 | AF21: 1.019 | AI21: =+AF21*AC21 -> 1072.3345 | AN21: 0.84 | AO21: =((AO20-AO22)/(AN20-AN22))*(AN21-AN22)+AO22 -> 0.6 | AP21: =AO21-(AO21-AQ21)/(AQ19-AO19)*(AP19-AO19) -> 1.104 | AQ21: =((AQ20-AQ22)/(AN20-AN22))*(AN21-AN22)+AQ22 -> 1 | AR21: =AN21+AR18 -> 0.841104 | AS21: +
A22: APT | G22: 0.01 | J22: 0.2 | M22: 1.021 | P22: =+M22*J22 -> 0.2042 | T22: =+A22 -> APT | Z22: 6.91 | AC22: 485.98 | AF22: 1.019 | AI22: =+AF22*AC22 -> 495.21362 | AN22: 1 | AO22: 3 | AQ22: 5 | AR22: =AN21-AR18 -> 0.838896 | AS22: -
A23: GRAY WT P | G23: 3.3 | J23: 28.98 | M23: 1 | P23: =+M23*J23 -> 28.98 | T23: =+A23 -> GRAY WT P | Z23: 6.15 | AC23: 52.95 | AF23: 1.019 | AI23: =+AF23*AC23 -> 53.95605
A24: GRAYWT S | G24: EMPTY | J24: 0 | M24: 0 | P24: =+M24*J24 -> 0 | T24: =+A24 -> GRAYWT S | Z24: EMPTY | AF24: 1.019 | AI24: =+AF24*AC24 -> 0 | AN24: SOUNDING | AP24: TRIM
T25: =+A25 -> 0 | W25: =+D25 -> 0 | Z25: 0 | AC25: 0 | AF25: 0 | AI25: =+AF25*AC25 -> 0 | AO25: 0 | AP25: 1 | AQ25: 1
T26: =+A26 -> 0 | W26: =+D26 -> 0 | Z26: 0 | AC26: 0 | AF26: 0 | AI26: =+AF26*AC26 -> 0 | AN26: 0.2 | AO26: 319.8 | AQ26: =AO26 -> 319.8
T27: =+A27 -> 0 | W27: =+D27 -> 0 | Z27: 0 | AC27: 0 | AF27: 0 | AI27: =+AF27*AC27 -> 0 | AN27: 0.84 | AO27: =((AO26-AO28)/(AN26-AN28))*(AN27-AN28)+AO28 -> 324.28 | AP27: =AO27-(AO27-AQ27)/(AQ25-AO25)*(AP25-AO25) -> 324.28 | AQ27: =((AQ26-AQ28)/(AN26-AN28))*(AN27-AN28)+AQ28 -> 324.28
T28: =+A28 -> 0 | W28: =+D28 -> 0 | Z28: 0 | AC28: 0 | AF28: 0 | AI28: =+AF28*AC28 -> 0 | AN28: 0.4 | AO28: 321.2 | AQ28: =AO28 -> 321.2
T29: =+A29 -> 0 | W29: =+D29 -> 0 | Z29: 0 | AC29: 0 | AF29: 0 | AI29: =+AF29*AC29 -> 0
D30: 0 | G30: 0 | J30: 0 | M30: 0 | P30: =+M30*J30 -> 0 | T30: =+A30 -> 0 | W30: =+D30 -> 0 | Z30: 0 | AC30: 0 | AF30: 0 | AI30: =+AF30*AC30 -> 0 | AN30: SOUNDING | AP30: TRIM
D31: 0 | G31: 0 | J31: 0 | M31: 0 | P31: =+M31*J31 -> 0 | T31: =+A31 -> 0 | W31: =+D31 -> 0 | Z31: 0 | AC31: 0 | AF31: 0 | AI31: =+AF31*AC31 -> 0 | AO31: 1 | AP31: 1.15 | AQ31: 2
D32: 0 | G32: 0 | J32: 0 | M32: 0 | P32: =+M32*J32 -> 0 | T32: =+A32 -> 0 | W32: =+D32 -> 0 | Z32: 0 | AC32: 0 | AF32: 0 | AI32: =+AF32*AC32 -> 0 | AN32: 0 | AQ32: =AO32 -> 0
D33: 0 | G33: 0 | J33: 0 | M33: 0 | P33: =+M33*J33 -> 0 | T33: =+A33 -> 0 | W33: =+D33 -> 0 | Z33: 0 | AC33: 0 | AF33: 0 | AI33: =+AF33*AC33 -> 0 | AN33: 6.476 | AO33: =((AO32-AO34)/(AN32-AN34))*(AN33-AN34)+AO34 -> 92.163074 | AP33: =AO33-(AO33-AQ33)/(AQ31-AO31)*(AP31-AO31) -> 92.163074 | AQ33: =((AQ32-AQ34)/(AN32-AN34))*(AN33-AN34)+AQ34 -> 92.163074
D34: 0 | G34: 0 | J34: 0 | M34: 0 | P34: =+M34*J34 -> 0 | T34: =+A34 -> 0 | W34: =+D34 -> 0 | Z34: 0 | AC34: 0 | AF34: 0 | AI34: =+AF34*AC34 -> 0 | AN34: 6.48 | AO34: 92.22 | AQ34: =AO34 -> 92.22
D35: 0 | G35: 0 | J35: 0 | M35: 0 | P35: =+M35*J35 -> 0 | T35: =+A35 -> 0 | W35: =+D35 -> 0 | Z35: 0 | AC35: 0 | AF35: 0 | AI35: =+AF35*AC35 -> 0
D36: 0 | G36: 0 | J36: 0 | M36: 0 | P36: =+M36*J36 -> 0 | T36: =+A36 -> 0 | W36: =+D36 -> 0 | Z36: 0 | AC36: 0 | AF36: 0 | AI36: =+AF36*AC36 -> 0 | AN36: SOUNDING | AP36: TRIM
D37: 0 | G37: 0 | J37: 0 | M37: 0 | P37: =+M37*J37 -> 0 | T37: =+A37 -> 0 | W37: =+D37 -> 0 | Z37: 0 | AC37: 0 | AF37: 0 | AI37: =+AF37*AC37 -> 0 | AO37: 2 | AP37: 0 | AQ37: 3
D38: 0 | G38: 0 | J38: 0 | M38: =+M37 -> 0 | P38: =+M38*J38 -> 0 | T38: =+A38 -> 0 | W38: =+D38 -> 0 | Z38: 0 | AC38: 0 | AF38: 0 | AI38: =+AF38*AC38 -> 0 | AN38: 3.4 | AO38: 245.3 | AQ38: 247.1
D39: 0 | G39: 0 | J39: 0 | M39: 0 | P39: =+M39*J39 -> 0 | T39: =+A39 -> 0 | W39: =+D39 -> 0 | Z39: 0 | AC39: 0 | AF39: 0 | AI39: =+AF39*AC39 -> 0 | AN39: 3.47 | AO39: =((AO38-AO40)/(AN38-AN40))*(AN39-AN40)+AO40 -> 253.63 | AP39: =AO39-(AO39-AQ39)/(AQ37-AO37)*(AP37-AO37) -> 252.83 | AQ39: =((AQ38-AQ40)/(AN38-AN40))*(AN39-AN40)+AQ40 -> 254.03
D40: 0 | G40: 0 | J40: 0 | M40: 0 | P40: =+M40*J40 -> 0 | T40: =+A40 -> 0 | W40: =+D40 -> 0 | Z40: 0 | AC40: 0 | AF40: 0 | AI40: =+AF40*AC40 -> 0 | AN40: 3.5 | AO40: 257.2 | AQ40: 257
D41: 0 | G41: 0 | J41: 0 | M41: 0 | P41: =+M41*J41 -> 0 | T41: =+A41 -> 0 | W41: =+D41 -> 0 | Z41: 0 | AC41: 0 | AF41: 0 | AI41: =+AF41*AC41 -> 0
B42: Total A | P42: =SUM(P11:R41) -> 120.40034 | U42: Total A | AI42: =SUM(AI11:AK41) -> 16346.655
A44: Tank | D44: Height | G44: Sounding | J44: Volume | M44: Density | P44: Total | T44: Tank | W44: Height | Z44: Sounding | AC44: Volume | AF44: Density | AI44: Total
...

Sheet Note of Protest SHORE SCALE 
A6: LETTER OF APPARENT DISCREPANCY
A8: VESSEL | E8: : | F8: =Draft!AB1 -> MV SANTA CAROLINA
A9: DATE | E9: : | F9: =Draft!AS2 -> 46221
A10: PORT | E10: : | F10: PUERTO MOIN - COSTA RICA
A11: BERTH | E11: : | F11: 5/3
A12: PRODUCT | E12: : | F12: YELLOW CORN
A13: PRINCIPALS | E13: : | F13: NOMBRE EL OWNER
A15: TO: FERTICA S.A. | B15: CARGUILL
A18: Mrss:
A19: We have been appointed as surveyors on the above named vessel by our principals and acting for and on their
A20: behalf, we do hereby note of protest with you concerning:
A23: =Draft!AB2 -> DDGS-SOYABEANS-YELLOW CORN
A24: BILL OF LADING | J24: 6000 | S24: MT
A25: CARGO DISCHARGED BY SHORE SCALE | J25: 6069.22 | S25: MT
A26: DIFFERENCE | J26: =+J25-J24 -> 69.22 | S26: MT
A27: PERCENTAGE % | J27: =+J26/J24 -> 0.011536667 | S27: MT
A30: We hereby reserve the right to this matter at letter of protest date and to take such actions as may be deemed necessary.
A32: Your´s faithfully | R32: RECEIVED by (Signature / Stamp)
A36: MSL Surveyor | R36: Cargo Receivers Representative
A40: Agent - Marinsa | R40: Vessel Representative

Sheet Note of Protest DRAFT
A6: LETTER OF APPARENT DISCREPANCY
A8: VESSEL | E8: : | F8: =Draft!AB1 -> MV SANTA CAROLINA
A9: DATE | E9: : | F9: =Draft!AS2 -> 46221
A10: PORT | E10: : | F10: PUERTO MOIN - COSTA RICA
A11: BERTH | E11: : | F11: 5/3
A12: PRODUCT | E12: : | F12: ='Note of Protest SHORE SCALE '!A23 -> DDGS-SOYABEANS-YELLOW CORN
A13: PRINCIPALS | E13: : | F13: ='Note of Protest SHORE SCALE '!F13 -> NOMBRE EL OWNER
A15: TO: FERTICA S.A. | B15: ='Note of Protest SHORE SCALE '!B15 -> CARGUILL
A18: Mrss:
A19: We have been appointed as surveyors on the above named vessel by our principals and acting for and on their
A20: behalf, we do hereby note of protest with you concerning:
A23: =Draft!AB2 -> DDGS-SOYABEANS-YELLOW CORN
A24: BILL OF LADING | J24: =Draft!AG35 -> 51045.42 | S24: MT
A25: CARGO DISCHARGED BY DRAFT SURVEY | J25: =Draft!AG34 -> 51122.536 | S25: MT
A26: DIFFERENCE | J26: =+J25-J24 -> 77.116413 | S26: MT
A27: PERCENTAGE % | J27: =+J26/J24 -> 0.0015107411 | S27: MT
A30: We hereby reserve the right to this matter at letter of protest date and to take such actions as may be deemed necessary.
A32: Your´s faithfully | R32: RECEIVED by (Signature / Stamp)
A36: MSL Surveyor | R36: Cargo Receivers Representative
A40: Agent - Marinsa | R40: Vessel Representative
