Workbook
Name AENTRADA: #REF!
Name AMOCO: #REF!
Name CERQUAN10: #REF!
Name CERQUAN4: #REF!
Name CERQUAN5: #REF!
Name CERQUAN6: #REF!
Name CERQUAN7: #REF!
Name cerquan8: #REF!
Name CERQUAN9: #REF!
Name COMPAR: [1]QVEF!$A$1:$W$41
Name CUAL: #REF!
Name EXXON: #REF!
Name EXXONMOBIL: #REF!
Name FOS_5299_01: #REF!
Name KOCH: #REF!
Name LOADSCALE: #REF!
Name LONG_MC_RAD: '[2]HYDROSTATIC TABLE'!#REF!
Name LYONDELL: #REF!
Name MARATHOS: #REF!
Name MOBIL: #REF!
Name OCENSA: #REF!
Name PARCELA1: #REF!
Name PARCELA2: #REF!
Name PARCELA3: #REF!
Name PARCELA4: #REF!
Name PARCELA5: #REF!
Name PARCELA6: #REF!
Name PARCELA9: #REF!
Name PROVER: #REF!
Name PROVERS: #REF!
Name QCKLST: #REF!
Name QCOMP: '[3]TELEX OCENSA'!$A$1:$J$259
Name QCOVER: #REF!
Name QDISCRP: #REF!
Name QSAPER: #REF!
Name QSHOMET: #REF!
Name SHICARGO: #REF!
Name SUMA: #REF!
Name TABLAS: Draft!$BA$2:$BD$20
Name TANULOD2: [4]TANULOD!$A$1:$L$36
Name TELEX: #REF!
Name TLXCOVE: #REF!
Name Vessel: [5]Data!$B$3
Name AENTRADA: #REF!
Name AMOCO: #REF!
Name CERQUAN10: #REF!
Name CERQUAN4: #REF!
Name CERQUAN5: #REF!
Name CERQUAN6: #REF!
Name CERQUAN7: #REF!
Name cerquan8: #REF!
Name CERQUAN9: #REF!
Name CUAL: #REF!
Name EXXON: #REF!
Name EXXONMOBIL: #REF!
Name FOS_5299_01: #REF!
Name KOCH: #REF!
Name LOADSCALE: #REF!
Name LONG_MC_RAD: '[2]HYDROSTATIC TABLE'!#REF!
Name LYONDELL: #REF!

Sheet A
A1: U.N. , ECE - DRAUGHT SURVEY CODE
AI2: FORM "A"
A3: DRAUGHT SURVEY REPORT OF CARGO IN BULK | Z3: =+Draft!AN3 | AA3: LOADED
Z4: =+Draft!AN4 | AA4: UNLOADED
B5: Corporate identification:
B6: MSL Marine Surveyors And Logistics
B7: Office of the surveyor at:
B8: =+General!A52
B9: Telephone no: | Q9: Fax no: | AD9: E-mail
B10: =++General!A54 | Q10: =+General!P54 | AD10: =+General!AC54
B11: Vessel M/V : | Q11: Call letters: | AD11: Survey no:
G12: =+Draft!AB1 | T12: =+General!AI3 | AG12: =+General!X3
B13: Vessel previous name/s: | AD13: Registry:
B14: =+General!J6 | AG14: =+General!M8
B15: Built year: | K15: By: | AD15: Flag:
B16: =+General!W8 | K16: =+General!AA8 | AG16: =+General!C8
B17: Survey requested by: | K17: =+General!AB12
B18: On the account of: | K18: =+General!AB13
B19: REMARKS | F19: =+General!A42
B24: This is to certify that the undersigned did, in Bona Fide, attend on board the subject vessel as she lay afloat
B25: at the port of: | H25: =IF(Draft!AN3="X",Draft!AB3,Draft!AB4) | R25: for the purpose of determining by draught computations the
B26: amount of | G26: =+'ECE DRAUGHT SURVEY CODE'!Y18&+" MT"
B27: loaded, unloaded (holds no. | K27: 1 & 3 | W27: ) and having followed the rules as set by the
B28: U.N. / ECE Uniform Code of Standards and Procedures for the Performance of Draught Surveys have the
B29: following to report:
I30: STARTING SURVEY | Z30: FINISHING SURVEY
H31: Attending the surveys: | I31: date D/M/Y: | N31: =+Draft!T2 | Z31: date D/M/Y: | AE31: =+Draft!AS2
I32: hours: from: | N32: =Draft!T3 | R32: to: | T32: =Draft!T4 | Z32: hours: from: | AE32: =Draft!AS3 | AI32: to: | AK32: =Draft!AS4
H33: Name of surveyor/s | J33: =+General!AB10 | AA33: =+General!AB11
H34: Master | J34: =+General!H10 | AA34: =+J34
AA35: =+J35
H36: Chief Officer | J36: =+General!H11 | AA36: =+J36
H37: Chief Engineer | J37: =+General!H12 | AA37: =+J37
H38: Witness draughts | J38: =+General!H13 | AA38: =+J38
AA39: =+J39
H40: Witness tank sounding | J40: =+General!H14 | AA40: =+J40
H42: Ship's location | J42: =+General!H16 | AA42: =+General!AB16
H43: Weather temperature | AA43: 0
H45: Sea condition | J45: =IF(Draft!I32="x","GOOD",IF(Draft!J32="X","LIGHT SHOPPY",IF(Draft!K32="X","HEAVY SHOPPY / SWELL"," "))) | AA45: =IF(Draft!I33="x","GOOD",IF(Draft!J33="X","LIGHT SHOPPY",IF(Draft!K33="X","HEAVY SHOPPY / SWELL"," ")))
H46: Heading of ship | J46: =IF(Draft!A8=0,0,"ALONGSIDE BERTH") | AA46: =IF(Draft!Z8=0,0,"ALONGSIDE BERTH")
...

Sheet B
A1: U.N. , ECE - DRAUGHT SURVEY CODE
AI2: FORM "B"
A3: DRAUGHT SURVEY REPORT OF CARGO IN BULK | Z3: =+A!Z3 | AA3: LOADED
Z4: =+A!Z4 | AA4: UNLOADED
B5: Corporate identification:
A6: =A!B6
B7: Vessel M/V : | Z7: Survey no:
F8: =+A!G12 | AC8: =+A!AG12
A9: General remarks by the surveyor/s
E11: Correction for stem and stern obtained by: | Y11: =+General!W34 | Z11: calculation | AF11: =+General!AC34 | AG11: tables
E12: Correction for trim (1) obtained by: | Y12: =+General!W35 | Z12: calculation | AF12: =+General!AC35 | AG12: tables
E13: Correction for trim (2) obtained by: | Y13: =+General!W36 | Z13: calculation | AF13: =+General!AC36 | AG13: tables
E14: Correction due to trim for liquid applied at: | Y14: =+General!W37 | Z14: soundings | AF14: =+General!AC37 | AG14: volumes
E15: Correction due to trim for liquid obtained by: | Y15: =+General!W38 | Z15: calculation | AF15: =+General!AC38 | AG15: tables
B17: Initial Draft Survey Remarks
B18: =+Draft!A38
B19: Final Draft Survey Remarks
B20: =+Draft!AB37
A21: Ship's approved hydrostatic tables and lightship information issued by and dated:
B22: =+General!A28
B24: Degree of tank calibration complies with code: | W24: =+General!W39 | X24: Yes | AA24: =+General!AC39 | AB24: No
B26: Range of trim correction tables available
B27: =IF(General!B30="X","YES",General!J30)
B28: Shipyard no. | S28: Hull no : | AC28: Dated at:
B30: Surveyor remarks on ship's documents
N32: metres | AE32: metric tonnes
A33: Length overall | N33: =+General!M18 | T33: Constant declared | AE33: =+General!AG18
A34: Length between p.p. | N34: =+General!M19 | T34: Constant calculated | AE34: =+General!AG19
A35: Extreme breadth | N35: =+General!M20 | T35: Light displacement | AE35: =+General!AG20
A36: Moulded breadth | N36: =+General!M21 | T36: Light shipweight (plan) | AE36: =+General!AG21
A37: Depth overall incl.. keel plate | N37: =+General!M22 | T37: Summer displacement | AE37: =+General!AG22
A38: Moulded depth | N38: =+General!M23 | T38: Summer deadweight | AE38: =+General!AG23
A39: Summer draught | N39: =+General!M24 | T39: Net register tons | AE39: =+General!AG24
A40: Summer freeboard | N40: =+General!M25 | T40: Gross register Tons | AE40: =+General!AG25
S42: STARTING SURVEY | AC42: FINISHING SURVEY
A43: Tonnes per Centimetre Immersion | S43: =+Draft!E16 | AC43: =+Draft!AD16
A44: Longitudinal Centre of Flotation | S44: =+Draft!A16 | AC44: =+Draft!Z16
A45: Distance marks forward pp. (forward - aft+) | S45: =+Draft!V8 | AC45: =+Draft!AU8
A46: Distance marks after pp. (forward - aft+) | S46: =+Draft!V10 | AC46: =+Draft!AU10
A47: Distance marks midship pp. (forward - aft+) | S47: =+Draft!V9 | AC47: =+Draft!AU9
...

Sheet C
A1: U.N. , ECE - DRAUGHT SURVEY CODE
AI2: FORM "C"
A3: DRAUGHT SURVEY REPORT OF CARGO IN BULK | Z3: =+A!Z3 | AA3: LOADED
Z4: =+A!Z4 | AA4: UNLOADED
B5: Corporate identification:
A6: =A!B6
B7: Vessel M/V : | Z7: Survey no:
F8: =+A!G12 | AC8: =+A!AG12
A9: DRAUGHT STATEMENT
A11: DRAUGHT READINGS HOURS: | S11: STARTING SURVEY | AE11: FINISHING SURVEY
S12: From | U12: =Draft!T3 | X12: To | Y12: =Draft!T4 | AE12: From | AG12: =Draft!AS3 | AJ12: To | AK12: =Draft!AS4
S13: metres | AE13: metres
B14: Draught forward port | S14: =+Draft!A8 | AE14: =+Draft!Z8
B15: Draught forward starboard | S15: =+Draft!E8 | AE15: =+Draft!AD8
B16: Draught forward mean | S16: =+Draft!J8 | AE16: =+Draft!AI8
B17: Stem correction | S17: =+Draft!N8 | AE17: =+Draft!AM8
B18: Draught forward (corrected to fore pp.) | S18: =+Draft!R8 | AE18: =+Draft!AQ8
B19: Draught after port | S19: =+Draft!A10 | AE19: =+Draft!Z10
B20: Draught after starboard | S20: =+Draft!E10 | AE20: =+Draft!AD10
B21: Draught after mean | S21: =+Draft!J10 | AE21: =+Draft!AI10
B22: Stem correction | S22: =+Draft!N10 | AE22: =+Draft!AM10
B23: Draught after (corrected to after pp.) | S23: =+Draft!R10 | AE23: =+Draft!AQ10
B24: Drought fore & after mean | S24: =(+S18+S23)/2 | AE24: =(+AE18+AE23)/2
B25: Draught midship port | S25: =+Draft!A9 | AE25: =+Draft!Z9
B26: Drought midship starboard | S26: =+Draft!E9 | AE26: =+Draft!AD9
B27: Draught midship mean | S27: =+Draft!J9 | AE27: =+Draft!AI9
B28: miadship correction | S28: =+Draft!N9 | AE28: =+Draft!AM9
B29: Draught midship (corrected to midship pp.) | S29: =+Draft!R9 | AE29: =+Draft!AQ9
B30: Sag (+) Hog (-) | S30: =+S27-(S16+S21)/2 | AE30: =+AE27-(AE16+AE21)/2
B31: Mean of means | S31: =+Draft!R13 | AE31: =+Draft!AQ13
B32: Draughl extreme corrected for hog/sag | S32: Nil | AE32: Nil
B33: Correction (-) for keel tickness it applicable | S33: =+S32 | AE33: =+AE32
B34: Draught moulded corrected for hog/sag | S34: =+S33 | AE34: =+AE33
B35: (Note: Utilize line 152 or line 154) | S35: =+S34 | AE35: =+AE34
B36: Trim: fwd(-) aft(+) | S36: =+Draft!E13 | AE36: =+Draft!AD13
S37: Kg/m3 | AE37: Kg/m3
B38: Observed density | S38: =+Draft!I13 | AE38: =+Draft!AH13
B39: (Ship's tables density Kg/m3 1.025 )
G40: Hydrometer no | M40: =+General!L32
S41: Metric tonnes | AE41: Metric tonnes
...

Sheet General
S1: Vessel M/V :
S3: Survey no: | AE3: Call letters:
A6: Vessel previous name/s:
A8: Flag: | I8: Registry: | S8: Built year: | Y8: By:
A10: Master | T10: Initial Surveyor/s
A11: Chief Officer | T11: Final Surveyor/s
A12: Chief Engineer | T12: Survey requested by:
A13: Witness draughts | H13: 0 | T13: On the account of:
A14: Witness sounding | H14: 0 | T14: Attended also by:
A16: Init Ship's location | T16: Final Ship's location
A18: Length overall | T18: Constant declared
A19: Length between p.p. | T19: Constant calculated
A20: Extreme breadth | T20: Light displacement
A21: Moulded breadth | T21: Light shipweight (plan)
A22: Depth overall incl.. keel plate | T22: Summer displacement
A23: Moulded depth | T23: Summer deadweight
A24: Summer draught | T24: Net register tons
A25: Summer freeboard | T25: Gross register Tons
A27: Ship's approved hydrostatic tables and lightship information issued by and dated:
A28: ABS JAN 12 /2001
B29: Range of trim correction tables available
B30: X | C30: YES | H30: NO
F32: Hydrometer no
F34: Correction for stem and stern obtained by: | W34: X | X34: calculation | AD34: tables | BC34: ARRIVAL TRIM CORRECTIONS FOR TANKS IS NOT COVERED BY VESSEL´S TABLES
F35: Correction for trim (1) obtained by: | W35: X | X35: calculation | AD35: tables
F36: Correction for trim (2) obtained by: | W36: X | X36: calculation | AD36: tables
F37: Correction due to trim for liquid applied at: | X37: soundings | AC37: X | AD37: volumes | BC37: The vessel should arrive with a trim out of the limits of trim covered by the trim corrections of the sounding tables and ballast tanks in slack conditions, and the Aft draft was not visible and properly referenced; due to previous fails at arrival, THE INITIAL OBTAINED FIGURE IS NOT RELIABLE. In addition, for the Final Draft, some ballast tanks were partially ballasted. THE ABNORMAL ARRIVAL CONDITION CAUSE THAT DRAFT SURVEY FIGURE ARE NOT RELIABLE, AND CAN´T BE USED AS LOADED/DISCHARGED CARGO FIGURE
F38: Correction due to trim for liquid obtained by: | W38: X | X38: calculation | AD38: tables
F39: Degree of tank calibration complies with code: | W39: X | X39: Yes | AD39: No
A41: Remarks regarding reliability of calculations
A51: Office of the surveyor at:
A52: Villa Bonita, Centro Comercial Villa Plaza Local N 6, Alajuela - Costa Rica
A53: Telephone no: | P53: Fax no: | AC53: E-mail
A54: 506- 2441 6408 Mobile: 506- 8814 0784 | P54: 506 - 2441 6408 / 506- 2441 6408 | AC54: pabel.mslogistics@yahoo.com

Sheet Draft
Q1: INITIAL SURVEY | AB1: =General!X1
Q2: DATE | Y2: CARGO | AP2: DATE | BB2: DISPL'S | BC2: LCF | BD2: MTC | BE2: APF | BG2: DRAFT | BH2: DISP | BI2: LCF | BJ2: MTC- | BK2: MTC+
Q3: FROM | Y3: FROM | AI3: LOADING | AP3: FROM | BA3: 1 | BB3: 4575.3 | BC3: =AL13/2-BF3 | BD3: 481 | BE3: =+BE4-(BE5-BE4) | BF3: 106.813 | BG3: =INT(BG4-1) | BH3: =VLOOKUP(BG3,TABLAS,2) | BI3: =VLOOKUP(BG3,TABLAS,3) | BJ3: =VLOOKUP(BG4-1.5,TABLAS,4) | BK3: =VLOOKUP(BG4-1+0.5+0.5,TABLAS,4)
Q4: TO | Y4: TO | AI4: UNLOADING | AN4: X | AP4: TO | BA4: 2 | BB4: 9536.2 | BC4: =AL13/2-BF4 | BD4: 540.8 | BE4: =+BE5-(BE6-BE5) | BF4: 106.355 | BG4: =+R13 | BH4: =VLOOKUP(BG4,TABLAS,2) | BI4: =VLOOKUP(BG4,TABLAS,3) | BJ4: =VLOOKUP(BG4-0.5,TABLAS,4) | BK4: =VLOOKUP(BG4+0.5,TABLAS,4)
Q5: : | BA5: 3 | BB5: 14695.8 | BC5: =AL13/2-BF5 | BD5: 582.2 | BF5: 105.723 | BG5: =INT(1+BG4) | BH5: =VLOOKUP(BG5,TABLAS,2) | BI5: =VLOOKUP(BG5,TABLAS,3) | BJ5: =VLOOKUP(BG4-0.5+1,TABLAS,4) | BK5: =VLOOKUP(BG4+1.5,TABLAS,4)
A6: I N I T I A L D R A F T S U R V E Y | Z6: F I N A L D R A F T S U R V E Y | BA6: 4 | BB6: 19987.8 | BC6: =AL13/2-BF6 | BD6: 613 | BF6: 105.041
A7: PORT | F7: STB | J7: MEAN | N7: Crrn. | R7: TRUE | V7: Marks | Z7: PORT | AE7: STB | AI7: MEAN | AM7: Crrn. | AQ7: TRUE | AU7: Marks | BA7: 5 | BB7: 25386.3 | BC7: =AL13/2-BF7 | BD7: 645.6 | BE7: =+BE6-BE5+BE6 | BF7: 103.992 | BG7: DRAFT | BH7: DISP | BI7: LCF | BJ7: MTC- | BK7: MTC+
J8: =(A8+E8)/2 | N8: =IF(A8=0,0,(+A13*-V8/(M13-V8-V10))) | R8: =+J8+N8 | AI8: =(Z8+AD8)/2 | AM8: =IF(Z8=0,0,(+Z13*-AU8/(AL13-AU8-AU10))) | AQ8: =+AI8+AM8 | AU8: =V8 | AY8: GG | BA8: 6 | BB8: 30889.1 | BC8: =AL13/2-BF8 | BD8: 678.4 | BE8: =+BE7-BE6+BE7 | BF8: 102.753 | BG8: =INT(BG9-1) | BH8: =VLOOKUP(BG8,TABLAS,2) | BI8: =VLOOKUP(BG8,TABLAS,3) | BJ8: =VLOOKUP(BG9-1.5,TABLAS,4) | BK8: =VLOOKUP(BG9-1+0.5+0.5,TABLAS,4)
J9: =(A9+E9)/2 | N9: =IF(A8=0,0,(+A13*-V9/(M13-V8-V10))) | R9: =+J9+N9 | AI9: =(Z9+AD9)/2 | AM9: =IF(Z8=0,0,(+Z13*-AU9/(AL13-AU8-AU10))) | AQ9: =+AI9+AM9 | AU9: =V9 | BA9: 7 | BB9: 36483.7 | BC9: =AL13/2-BF9 | BD9: 713 | BE9: =+BE8-BE7+BE8 | BF9: 101.278 | BG9: =+AQ13 | BH9: =VLOOKUP(BG9,TABLAS,2) | BI9: =VLOOKUP(BG9,TABLAS,3) | BJ9: =VLOOKUP(BG9-0.5,TABLAS,4) | BK9: =VLOOKUP(BG9+0.5,TABLAS,4)
J10: =(A10+E10)/2 | N10: =IF(A8=0,0,(+A13*V10/(M13-V8-V10))) | R10: =+J10+N10 | AI10: =(Z10+AD10)/2 | AM10: =IF(Z8=0,0,(+Z13*AU10/(AL13-AU8-AU10))) | AQ10: =+AI10+AM10 | AU10: =V10 | BA10: 8 | BB10: 42178.3 | BC10: =AL13/2-BF10 | BD10: 753 | BE10: =+BE9-BE8+BE9 | BF10: 99.573 | BG10: =INT(1+BG9) | BH10: =VLOOKUP(BG10,TABLAS,2) | BI10: =VLOOKUP(BG10,TABLAS,3) | BJ10: =VLOOKUP(BG9-0.5+1,TABLAS,4) | BK10: =VLOOKUP(BG9+1.5,TABLAS,4)
BA11: 9 | BB11: 47982.5 | BC11: =AL13/2-BF11 | BD11: 798.4 | BE11: =+BE10-BE9+BE10 | BF11: 97.704
A12: A.Trim | E12: T.Trim | I12: S.G. | M12: LPP | R12: MMM | Z12: A.Trim | AD12: T.Trim | AH12: S.G. | AL12: LPP | AQ12: MMM | BA12: 10 | BB12: 53901.1 | BC12: =AL13/2-BF12 | BD12: 848.2 | BE12: =+BE11-BE10+BE11 | BF12: 95.765 | BG12: DISP | BH12: TPC | BI12: LCF | BJ12: MTC+50 | BK12: MTC-50
A13: =+J10-J8 | E13: =+R10-R8 | R13: =(6*R9+R8+R10)/8 | Z13: =+AI10-AI8 | AD13: =+AQ10-AQ8 | AL13: =+M13 | AQ13: =(6*AQ9+AQ8+AQ10)/8 | BA13: 11 | BB13: 59939.7 | BC13: =AL13/2-BF13 | BD13: 891.5 | BE13: =+BE12-BE11+BE12 | BF13: 94.165 | BG13: =(BH5-BH4*2+BH3)*BG15/3 | BH13: =(BH5-BH4*2+BH3)*BH15/3 | BI13: =(BI5-BI4*2+BI3)*BI15/3 | BJ13: =(BK5-BK4*2+BK3)*BJ15/3 | BK13: =(BJ5-BJ4*2+BJ3)*BK15/3
BA14: 12 | BB14: 66047 | BC14: =AL13/2-BF14 | BD14: 909.1 | BE14: =+BE13-BE12+BE13 | BF14: 93.552 | BG14: =+BG4-INT(BG4) | BH14: =+BG4+0.01-INT(BG4) | BI14: =+BG4-INT(BG4) | BJ14: =+BG4+0.5-INT(BG4+0.5) | BK14: =+BG4-0.5-INT(BG4-0.5)
A15: LCF | E15: TPC | I15: MTC+50 | M15: MTC-50 | Q15: TPC - P | U15: TPC - S | Z15: LCF | AD15: TPC | AH15: MTC+50 | AL15: MTC-50 | AP15: TPC - P | AT15: TPC - S | BA15: 13 | BB15: 72190.4 | BC15: =AL13/2-BF15 | BD15: 920.1 | BE15: =+BE14-BE13+BE14 | BF15: 93.305 | BG15: =IF(BG14>0.5,1-BG14,BG14) | BH15: =IF(BH14>0.5,1-BH14,BH14) | BI15: =IF(BI14>0.5,1-BI14,BI14) | BJ15: =IF(BJ14>0.5,1-BJ14,BJ14) | BK15: =IF(BK14>0.5,1-BK14,BK14)
A16: =BJ28 | E16: =BI28 | I16: =BH32 | M16: =BJ32 | Z16: =BJ37 | AD16: =BI37 | AH16: =BH41 | AL16: =BJ41 | BA16: 14 | BB16: 78359.4 | BC16: =AL13/2-BF16 | BD16: 928.4 | BE16: =+BE15-BE14+BE15 | BF16: 93.282 | BH16: =((BH5-BH4)*BH14+BH4-BH13+0.5)
BA17: 15 | BB17: 84548.1 | BC17: =AL13/2-BF17 | BD17: 935.2 | BE17: =+BE16-BE15+BE16 | BF17: 93.431 | BG17: =((BH5-BH4)*BG14+BH4-BG13+0.5) | BH17: =+BH16-BG17 | BI17: =((BI5-BI4)*BI14+BI4-BI13) | BJ17: =((BK5-BK4)*BJ14+BK4-BJ13) | BK17: =((BJ5-BJ4)*BK14+BJ4-BK13)
A18: BALLAST | M18: =BH28 | S18: DISPLACEMENT | AG18: =BH37 | AM18: BALLAST | AS18: =Deductions!AI42 | BA18: 16 | BB18: =+BB17-BB16+BB17 | BC18: =+BC17-BC16+BC17 | BD18: =+BD17-BD16+BD17 | BE18: =+BE17-BE16+BE17 | BG18: DISP | BH18: TPC | BI18: LCF | BJ18: MTC+50 | BK18: MTC-50
A19: F.WATER | M19: =ROUND(IF($S$19="Y",(((R13*100)-TRUNC(R13*100))*E16),0),2) | S19: N | T19: DECIMAL CORRECTION | AG19: =ROUND(IF($S$19="Y",(((AQ13*100)-TRUNC(AQ13*100))*AD16),0),2) | AM19: F.WATER | AS19: =Deductions!AI54 | BA19: 17 | BB19: =+BB18-BB17+BB18 | BC19: =+BC18-BC17+BC18 | BD19: =+BD18-BD17+BD18 | BE19: =+BE18-BE17+BE18 | BG19: =(BH10-BH9*2+BH8)*BG21/3 | BH19: =(BH10-BH9*2+BH8)*BH21/3 | BI19: =(BI10-BI9*2+BI8)*BI21/3 | BJ19: =(BK10-BK9*2+BK8)*BJ21/3 | BK19: =(BJ10-BJ9*2+BJ8)*BK21/3
A20: FUEL OIL | M20: =+M19+M18 | S20: DRAFT DISPLACEMENT | AG20: =+AG19+AG18 | AM20: FUEL OIL | BA20: 18 | BB20: =+BB19-BB18+BB19 | BC20: =+BC19-BC18+BC19 | BD20: =+BD19-BD18+BD19 | BE20: =+BE19-BE18+BE19 | BG20: =+BG9-INT(BG9) | BH20: =+BG9+0.01-INT(BG9) | BI20: =+BG9-INT(BG9) | BJ20: =+BG9+0.5-INT(BG9+0.5) | BK20: =+BG9-0.5-INT(BG9-0.5)
A21: DIESEL OIL | M21: =IF($M$18=0,0,(100*A16*E16*E13/M13)) | S21: TRIM CORRECTION "A" | AG21: =IF($AG$18=0,0,(100*Z16*AD16*AD13/AL13)) | AM21: DIESEL OIL | BG21: =IF(BG20>0.5,1-BG20,BG20) | BH21: =IF(BH20>0.5,1-BH20,BH20) | BI21: =IF(BI20>0.5,1-BI20,BI20) | BJ21: =IF(BJ20>0.5,1-BJ20,BJ20) | BK21: =IF(BK20>0.5,1-BK20,BK20)
A22: LUB OIL | M22: =IF($M$18=0,0,(50*E13*E13*(I16-M16)/M13)) | S22: TRIM CORRECTION "B" | AG22: =IF($AG$18=0,0,(50*AD13*AD13*(AH16-AL16)/AL13)) | AM22: LUB OIL | BA22: =+BI17 | BB22: LCF | BD22: =+BI23 | BH22: =((BH10-BH9)*BH20+BH9-BH19+0.5)
A23: SLOP | G23: 0 | M23: =+M21+M22 | S23: TOTAL TRIM CORRECTIONS | AG23: =+AG21+AG22 | AM23: SLOP | AS23: 0 | BA23: =+BH17 | BB23: TPC | BD23: =+BH23 | BG23: =((BH10-BH9)*BG20+BH9-BG19+0.5) | BH23: =+BH22-BG23 | BI23: =((BI10-BI9)*BI20+BI9-BI19) | BJ23: =((BK10-BK9)*BJ20+BK9-BJ19) | BK23: =((BJ10-BJ9)*BK20+BJ9-BK19)
A24: S, POOL | G24: 0 | M24: =ROUND(6*(Q16-U16)*(A9-E9),2) | S24: LIST CORRECTION | AG24: =ROUND(6*(AP16-AT16)*(Z9-AD9),2) | AM24: S, POOL | AS24: 0 | BA24: =+BJ17 | BB24: MTC+50 | BD24: =+BJ23
A25: OTHERS | M25: =+M20+M23+M24 | S25: CORRECTED DISPLACEMENT | AG25: =+AG20+AG23+AG24 | AM25: OTHERS | BA25: =+BK17 | BB25: MTC-50 | BD25: =+BK23
A26: DEDUCTIONS | G26: =SUM(G18:K25) | M26: =((I13-1.025)*M25)/1.025 | S26: DENSITY CORRECTION | AG26: =((AH13-1.025)*AG25)/1.025 | AM26: DEDUCTIONS | AS26: =SUM(AS18:AW25) | BA26: =+BG17 | BB26: DRAFT DISPLACEMENT | BD26: =+BG23 | BG26: DRAFT | BH26: DISP | BI26: TPC | BJ26: LCF | BK26: LCB
A27: CONDITIONS | I27: GOOD | J27: REG | K27: BAD | M27: =+M25+M26 | S27: TRUE DISPLACEMENT | AG27: =+AG25+AG26 | BA27: =100*BA22*BA23*E13/M13 | BB27: TRIM CORRECTION "A" | BD27: =100*BD22*BD23*AD13/M13 | BK27: =M13
M28: =+G26 | S28: TOTAL DEDUCTIONS | AG28: =+AS26 | BA28: =50*E13*E13*(BA24-BA25)/M13 | BB28: TRIM CORRECTION "B" | BD28: =50*Z13*AD13*(BD24-BD25)/M13 | BG28: =+BG4 | BH28: =BH27+(BG28-BG27)*(BH29-BH27)/(BG29-BG27) | BI28: =BI27+(BG28-BG27)*(BI29-BI27)/(BG29-BG27) | BJ28: =BJ27+(BG28-BG27)*(BJ29-BJ27)/(BG29-BG27) | BK28: =BK27/2
S29: LIGHT SHIP | AG29: =IF(AG18=0,0,M29) | AN29: =General!H11 | BA29: =+BA27+BA28 | BB29: TOTAL TRIM CORRECTIONS | BD29: =+BD27+BD28 | BK29: 103.577
A30: SOUNDING PIPES | I30: X | S30: HISTORIC CONSTANT | AR30: CHIEF OFFICER | BB30: LIST CORRECTION | BG30: 42452.2 | BH30: MTC +50 | BI30: DRAFT - | BJ30: MTC - 50 | BK30: =BK28-BK29
A31: DRAFT MARKS | I31: X | M31: =IF(M30=0,(M27-M28-M29),0) | S31: CONSTANT "K" | AG31: =IF(AG18=0,0,(IF(M30=0,M31,AG27-AG28-AG29))) | BA31: =+BA26+BA29+BA30 | BB31: CORRECTED DISP. | BD31: =+BD26+BD29+BD30 | BI31: =+BG31-1
A32: SWELL INITIAL | J32: X | M32: =+M27-M28 | S32: INITIAL NET LIGHT DISPLACEMENT | AG32: =IF(AG18=0,0,M32) | AN32: =General!H10 | BA32: =+BA31-M25 | BB32: DIFFERENCE | BD32: =+BD31-AG25 | BG32: =+BG28+0.5 | BH32: =BH31+(BG32-BG31)*(BH33-BH31)/(BG33-BG31) | BI32: =+BG32-1 | BJ32: =BJ31+(BI32-BI31)*(BJ33-BJ31)/(BI33-BI31)
A33: SWELL FINAL | J33: X | S33: FINAL NET LIGHT DISPLACEMENT | AG33: =+AG27-AG28 | AR33: MASTER | BG33: =BG29+0.5 | BI33: =+BG33-1
A34: HYDROSTATIC TB. | I34: X | M34: =IF(M30=0,M31,M27-M28-M29-M30) | S34: INIT FIGURE | Y34: SURVEY FIGURE | AG34: =ABS(+AG32-AG33) | BB34: INITIAL
A35: DISTANCE TO MARKS | I35: X | S35: B/L FIGURE | AN35: =General!AB10 | BA35: =+A8 | BB35: =+BB36 | BC35: =BA35+BB35*((BC36-BA36)/BB36) | BG35: DRAFT | BH35: DISP | BI35: TPC | BJ35: LCF
A36: BALLAST TABLES | I36: X | M36: =+M34-M35 | S36: DIFFERENCE | AG36: =+AG34-AG35 | AR36: MSL SURVEYOR | BA36: =+A9 | BB36: =+General!M21 | BC36: =+E9
A37: Head Office – Alajuela, Plaa Aeropuerto Local G-14 - Phone (506) 8814-07-84 – Tele (506) 4037-5903 www.mslogisticsgroup.com | BA37: =+A10 | BB37: =+BB36 | BC37: =BA37+BB37*((BC36-BA36)/BB36) | BG37: =+AQ13 | BH37: =BH36+(BG37-BG36)*(BH38-BH36)/(BG38-BG36) | BI37: =BI36+(BG37-BG36)*(BI38-BI36)/(BG38-BG36) | BJ37: =BJ36+(BG37-BG36)*(BJ38-BJ36)/(BG38-BG36)
A38: REMARK: Swell Condition, Initial ( 0,10 to 0.20 Mtr) / Final Draft ( 0,10 to 0,20 Mtr) | BA38: LIST = | BB38: =ROUND((ATAN((BA36-BC36)/BB36)*180/PI()),2) | BC38: º
BA39: =BC39+BB39*((BA40-BC40)/BB40) | BB39: =+BB40 | BC39: =+E8 | BG39: DRAFT + | BH39: MTC +50 | BI39: DRAFT - | BJ39: MTC - 50
BA40: =+A9 | BB40: =+BB36 | BC40: =+E9 | BI40: =+BG40-1
...

Sheet Deductions
A1: ,
A2: DATE | D2: =+Draft!T2 | H2: FROM | K2: =Draft!T3 | N2: TO | P2: =Draft!T4 | T2: DATE | W2: =+Draft!AS2 | AA2: FROM | AD2: =Draft!AS3 | AG2: TO | AI2: =Draft!AS4
A4: SI HAY DIFERENCIAS ENTRE LAS DISTANCIAS DE LAS SONDAS DE DOS TANQUES | AD4: *** POSIBLY OBSTRUCTION
A5: GEMELOS (EJ. TST 2 P Y TST 2S) SE DEBE CLOCAR UN ASTERISCO EN EL
A6: NOMBRE DEL TANQUE, Y MARCAR CON "X" LA CASILLA DE POSIBLE OBSTRUCCION
A8: Tank | D8: Height | G8: Sounding | J8: Volume | M8: Density | P8: Total | T8: Tank | W8: Height | Z8: Sounding | AC8: Volume | AF8: Density | AI8: Total
A10: INITIAL BALLAST | T10: FINAL BALLAST
D11: 0 | P11: =+M11*J11 | AI11: =+AF11*AC11 | AR11: =AP15/AR13
D12: 0 | P12: =+M12*J12 | AI12: =+AF12*AC12 | AN12: SOUNDING | AP12: TRIM | AR12: CORRECCION SONDA M.M
D13: 0 | P13: =+M13*J13 | AI13: =+AF13*AC13 | AO13: 2 | AP13: 2.42 | AQ13: 2.5 | AR13: 1000
D14: 0 | P14: =+M14*J14 | AI14: =+AF14*AC14 | AN14: 1 | AO14: 487.6 | AQ14: 489.9 | AR14: =AN15+AR11 | AS14: +
D15: 0 | P15: =+M15*J15 | AI15: =+AF15*AC15 | AN15: 1.08 | AO15: =((AO14-AO16)/(AN14-AN16))*(AN15-AN16)+AO16 | AP15: =AO15-(AO15-AQ15)/(AQ13-AO13)*(AP13-AO13) | AQ15: =((AQ14-AQ16)/(AN14-AN16))*(AN15-AN16)+AQ16 | AR15: =AN15-AR11 | AS15: -
D16: 0 | P16: =+M16*J16 | AI16: =+AF16*AC16 | AN16: 1.1 | AO16: 511.2 | AQ16: 513.5 | AU16: =AN15-0.0339
D17: 0 | P17: =+M17*J17 | AI17: =+AF17*AC17
D18: 0 | P18: =+M18*J18 | AI18: =+AF18*AC18 | AN18: SOUNDING | AP18: HEEL | AR18: =AP21/AR20 | AU18: 0.064
D19: 0 | P19: =+M19*J19 | AI19: =+AF19*AC19 | AO19: 1 | AP19: =AP13 | AQ19: 2 | AR19: CORRECCION SONDA M.M | AU19: =AN15-AU18
D20: 0 | P20: =+M20*J20 | AI20: =+AF20*AC20 | AN20: 0.8 | AO20: 0 | AQ20: 0 | AR20: 1000
D21: 0 | P21: =+M21*J21 | AI21: =+AF21*AC21 | AN21: 0.84 | AO21: =((AO20-AO22)/(AN20-AN22))*(AN21-AN22)+AO22 | AP21: =AO21-(AO21-AQ21)/(AQ19-AO19)*(AP19-AO19) | AQ21: =((AQ20-AQ22)/(AN20-AN22))*(AN21-AN22)+AQ22 | AR21: =AN21+AR18 | AS21: +
P22: =+M22*J22 | AI22: =+AF22*AC22 | AN22: 1 | AO22: 3 | AQ22: 5 | AR22: =AN21-AR18 | AS22: -
P23: =+M23*J23 | AI23: =+AF23*AC23
P24: =+M24*J24 | AI24: =+AF24*AC24 | AN24: SOUNDING | AP24: TRIM
W25: =+D25 | Z25: 0 | AC25: 0 | AF25: 0 | AI25: =+AF25*AC25 | AO25: 0 | AP25: 1 | AQ25: 1
T26: =+A26 | W26: =+D26 | Z26: 0 | AC26: 0 | AF26: 0 | AI26: =+AF26*AC26 | AN26: 0.2 | AO26: 319.8 | AQ26: =AO26
T27: =+A27 | W27: =+D27 | Z27: 0 | AC27: 0 | AF27: 0 | AI27: =+AF27*AC27 | AN27: 0.84 | AO27: =((AO26-AO28)/(AN26-AN28))*(AN27-AN28)+AO28 | AP27: =AO27-(AO27-AQ27)/(AQ25-AO25)*(AP25-AO25) | AQ27: =((AQ26-AQ28)/(AN26-AN28))*(AN27-AN28)+AQ28
T28: =+A28 | W28: =+D28 | Z28: 0 | AC28: 0 | AF28: 0 | AI28: =+AF28*AC28 | AN28: 0.4 | AO28: 321.2 | AQ28: =AO28
T29: =+A29 | W29: =+D29 | Z29: 0 | AC29: 0 | AF29: 0 | AI29: =+AF29*AC29
D30: 0 | G30: 0 | J30: 0 | M30: 0 | P30: =+M30*J30 | T30: =+A30 | W30: =+D30 | Z30: 0 | AC30: 0 | AF30: 0 | AI30: =+AF30*AC30 | AN30: SOUNDING | AP30: TRIM
D31: 0 | G31: 0 | J31: 0 | M31: 0 | P31: =+M31*J31 | T31: =+A31 | W31: =+D31 | Z31: 0 | AC31: 0 | AF31: 0 | AI31: =+AF31*AC31 | AO31: 1 | AP31: 1.15 | AQ31: 2
D32: 0 | G32: 0 | J32: 0 | M32: 0 | P32: =+M32*J32 | T32: =+A32 | W32: =+D32 | Z32: 0 | AC32: 0 | AF32: 0 | AI32: =+AF32*AC32 | AN32: 0 | AQ32: =AO32
D33: 0 | G33: 0 | J33: 0 | M33: 0 | P33: =+M33*J33 | T33: =+A33 | W33: =+D33 | Z33: 0 | AC33: 0 | AF33: 0 | AI33: =+AF33*AC33 | AN33: 6.476 | AO33: =((AO32-AO34)/(AN32-AN34))*(AN33-AN34)+AO34 | AP33: =AO33-(AO33-AQ33)/(AQ31-AO31)*(AP31-AO31) | AQ33: =((AQ32-AQ34)/(AN32-AN34))*(AN33-AN34)+AQ34
D34: 0 | G34: 0 | J34: 0 | M34: 0 | P34: =+M34*J34 | T34: =+A34 | W34: =+D34 | Z34: 0 | AC34: 0 | AF34: 0 | AI34: =+AF34*AC34 | AN34: 6.48 | AO34: 92.22 | AQ34: =AO34
D35: 0 | G35: 0 | J35: 0 | M35: 0 | P35: =+M35*J35 | T35: =+A35 | W35: =+D35 | Z35: 0 | AC35: 0 | AF35: 0 | AI35: =+AF35*AC35
D36: 0 | G36: 0 | J36: 0 | M36: 0 | P36: =+M36*J36 | T36: =+A36 | W36: =+D36 | Z36: 0 | AC36: 0 | AF36: 0 | AI36: =+AF36*AC36 | AN36: SOUNDING | AP36: TRIM
D37: 0 | G37: 0 | J37: 0 | M37: 0 | P37: =+M37*J37 | T37: =+A37 | W37: =+D37 | Z37: 0 | AC37: 0 | AF37: 0 | AI37: =+AF37*AC37 | AO37: 2 | AP37: 0 | AQ37: 3
D38: 0 | G38: 0 | J38: 0 | M38: =+M37 | P38: =+M38*J38 | T38: =+A38 | W38: =+D38 | Z38: 0 | AC38: 0 | AF38: 0 | AI38: =+AF38*AC38 | AN38: 3.4 | AO38: 245.3 | AQ38: 247.1
D39: 0 | G39: 0 | J39: 0 | M39: 0 | P39: =+M39*J39 | T39: =+A39 | W39: =+D39 | Z39: 0 | AC39: 0 | AF39: 0 | AI39: =+AF39*AC39 | AN39: 3.47 | AO39: =((AO38-AO40)/(AN38-AN40))*(AN39-AN40)+AO40 | AP39: =AO39-(AO39-AQ39)/(AQ37-AO37)*(AP37-AO37) | AQ39: =((AQ38-AQ40)/(AN38-AN40))*(AN39-AN40)+AQ40
D40: 0 | G40: 0 | J40: 0 | M40: 0 | P40: =+M40*J40 | T40: =+A40 | W40: =+D40 | Z40: 0 | AC40: 0 | AF40: 0 | AI40: =+AF40*AC40 | AN40: 3.5 | AO40: 257.2 | AQ40: 257
D41: 0 | G41: 0 | J41: 0 | M41: 0 | P41: =+M41*J41 | T41: =+A41 | W41: =+D41 | Z41: 0 | AC41: 0 | AF41: 0 | AI41: =+AF41*AC41
B42: Total A | P42: =SUM(P11:R41) | U42: Total A | AI42: =SUM(AI11:AK41)
A44: Tank | D44: Height | G44: Sounding | J44: Volume | M44: Density | P44: Total | T44: Tank | W44: Height | Z44: Sounding | AC44: Volume | AF44: Density | AI44: Total
...

Sheet ECE DRAUGHT SURVEY CODE
A1: U.N. , ECE - DRAUGHT SURVEY CODE
AI2: FORM "E"
A3: DRAUGHT SURVEY REPORT OF CARGO IN BULK | Z3: =+A!Z3 | AA3: LOADED
Z4: =+A!Z4 | AA4: UNLOADED
B5: Corporate identification:
A6: =A!B6
B7: Vessel M/V : | Z7: Survey no:
F8: =+A!G12 | AC8: =+A!AG12
A9: CARGO STATEMENT
Y11: Metric Tonnes
A14: Starting Displacement Corrected | Y14: =+Draft!M32
A16: Finishing Displacement Corrected | Y16: =+Draft!AG33
A18: Difference in Displacement = TOTAL CARGO IN BULK IS: | Y18: =ROUND(+Draft!AG34,2)
B20: OBSERVATIONS: Shore scale quantity (if available) M.T.
B21: Note on any unusual situatonts, exception/s from required Uniform Code standard, specific identification
B22: (source, drawing no., date, title. certifying authority) of each ships document used in translating recorded
B23: measurements lrvto weights and, when applicable, reasons for surveyors refusal or impossibility to perform
B24: the survey:
X27: Metric Tonnes
A28: Corrected light displacement = | X28: =IF(Y16=0,0,IF(Y14=0,0,IF(Draft!M27>Draft!AG27,Draft!M27,Draft!AG27)))
A29: Deductables = | X29: =IF(X28=0,0,IF(Draft!M27>Draft!AG27,Draft!G26,Draft!AS26))
A30: Lightship = | X30: =IF(X29=0,0,+Draft!AG29)
A31: Constant = | X31: =IF(X30=0,0,+Draft!AG31)
A32: Mean of previous constants =
B35: I certify that the constant calculated from this draught survey has been entered into the ship's 'Constant Certificate'
B38: In my judgement the weather conditions, the sea conditions, and the conditions of the ship at the times the
B39: draught surveys were conducted, were within acceptable limits and did not adversely affect the accuracy of
B40: this survey. This Bona Fide report consisting of 4 pages, including this page, all duly initialled or signed
B41: is issued without prejudice and is for the benefit of whom It may concern.
B45: Name at surveying firm
B47: By: | AB47: =A!B6
B48: (Signature of Surveyor/s)
B50: Name/s in print | H50: =CONCATENATE(AB54," - ",AB56," - ",General!AB10)
A51: I have participated in all stages of this draught survey, and agree with the results obtained. I acknowledge receipt of the ship's copy.
B53: Signed: | M53: Rank: | T53: Name in print:
M54: MASTER | AB54: =+General!H10
M56: CHIEF OFFICER | AB56: =+General!H11

Sheet Draught survey report
A1: U.N. , ECE - DRAUGHT SURVEY CODE
AI2: FORM "D1"
A3: DRAUGHT SURVEY REPORT OF CARGO IN BULK | Z3: =+A!Z3 | AA3: LOADED
Z4: =+A!Z4 | AA4: UNLOADED
B5: Corporate identification:
A6: =A!B6
B7: Vessel M/V : | Z7: Survey no:
F8: =+A!G12 | AC8: =+A!AG12
A9: STARTING SOUNDING: | K9: From Hours: | S9: To Hours | AB9: Date: | AJ9: Trim:
K10: =Draft!T3 | S10: =Draft!T4 | AB10: =+Draft!T2 | AJ10: =+Draft!E13 | AN10: M
S11: Sounding
A12: Compartment Title. | I12: Maximun | N12: Sounding | S12: / ullage | X12: Volume | AD12: Density of | AJ12: Total
B13: * Tank no. | I13: height | N13: / ullage | S13: corrected for | X13: corrected | AD13: Water | AJ13: weight
B14: * Bilges | I14: meausured (*) | N14: metres | S14: trim / list | X14: for trim / list | AD14: in air | AJ14: Metric
B15: * Duct Keel | I15: metres | S15: metres | X15: m3 | AD15: Kg/m3 | AJ15: tonnes
B16: A - BALLAST
B18: =+Deductions!A11 | I18: =+Deductions!D11 | N18: =+Deductions!G11 | X18: =+Deductions!J11 | AD18: =+Deductions!M11 | AJ18: =+Deductions!P11
B19: =+Deductions!A12 | I19: =+Deductions!D12 | N19: =+Deductions!G12 | X19: =+Deductions!J12 | AD19: =+Deductions!M12 | AJ19: =+Deductions!P12
B20: =+Deductions!A13 | I20: =+Deductions!D13 | N20: =+Deductions!G13 | X20: =+Deductions!J13 | AD20: =+Deductions!M13 | AJ20: =+Deductions!P13
B21: =+Deductions!A14 | I21: =+Deductions!D14 | N21: =+Deductions!G14 | X21: =+Deductions!J14 | AD21: =+Deductions!M14 | AJ21: =+Deductions!P14
B22: =+Deductions!A15 | I22: =+Deductions!D15 | N22: =+Deductions!G15 | X22: =+Deductions!J15 | AD22: =+Deductions!M15 | AJ22: =+Deductions!P15
B23: =+Deductions!A16 | I23: =+Deductions!D16 | N23: =+Deductions!G16 | X23: =+Deductions!J16 | AD23: =+Deductions!M16 | AJ23: =+Deductions!P16
B24: =+Deductions!A17 | I24: =+Deductions!D17 | N24: =+Deductions!G17 | X24: =+Deductions!J17 | AD24: =+Deductions!M17 | AJ24: =+Deductions!P17
B25: =+Deductions!A18 | I25: =+Deductions!D18 | N25: =+Deductions!G18 | X25: =+Deductions!J18 | AD25: =+Deductions!M18 | AJ25: =+Deductions!P18
B26: =+Deductions!A19 | I26: =+Deductions!D19 | N26: =+Deductions!G19 | X26: =+Deductions!J19 | AD26: =+Deductions!M19 | AJ26: =+Deductions!P19
B27: =+Deductions!A20 | I27: =+Deductions!D20 | N27: =+Deductions!G20 | X27: =+Deductions!J20 | AD27: =+Deductions!M20 | AJ27: =+Deductions!P20
B28: =+Deductions!A21 | I28: =+Deductions!D21 | N28: =+Deductions!G21 | X28: =+Deductions!J21 | AD28: =+Deductions!M21 | AJ28: =+Deductions!P21
B29: =+Deductions!A22 | I29: =+Deductions!D22 | N29: =+Deductions!G22 | X29: =+Deductions!J22 | AD29: =+Deductions!M22 | AJ29: =+Deductions!P22
... B44: =+Deductions!A37 | I44: =+Deductions!D37 | N44: =+Deductions!G37 | X44: =+Deductions!J37 | AD44: =+Deductions!M37 | AJ44: =+Deductions!P37
B45: Total A | AJ45: =+Deductions!P42
B46: B - FRESH WATER
B48: =+Deductions!A47 | I48: =+Deductions!D47 | N48: =+Deductions!G47 | X48: =+Deductions!J47 | AD48: =+Deductions!M47 | AJ48: =+Deductions!P47
B49: =+Deductions!A48 | I49: =+Deductions!D48 | N49: =+Deductions!G48 | X49: =+Deductions!J48 | AD49: =+Deductions!M48 | AJ49: =+Deductions!P48
B50: =+Deductions!A49 | I50: =+Deductions!D49 | N50: =+Deductions!G49 | X50: =+Deductions!J49 | AD50: =+Deductions!M49 | AJ50: =+Deductions!P49
B51: =+Deductions!A50 | I51: =+Deductions!D50 | N51: =+Deductions!G50 | X51: =+Deductions!J50 | AD51: =+Deductions!M50 | AJ51: =+Deductions!P50
B52: =+Deductions!A51 | I52: =+Deductions!D51 | N52: =+Deductions!G51 | X52: =+Deductions!J51 | AD52: =+Deductions!M51 | AJ52: =+Deductions!P51
B53: =+Deductions!A52 | I53: =+Deductions!D52 | N53: =+Deductions!G52 | X53: =+Deductions!J52 | AD53: =+Deductions!M52 | AJ53: =+Deductions!P52
B54: Total B | AJ54: =+Deductions!P54
C56: =IF(Deductions!AC4="X", Deductions!AD4," ")

Sheet ECE DRAUGHT SURVEY CODE D2
A1: U.N. , ECE - DRAUGHT SURVEY CODE
AI2: FORM "D2"
A3: DRAUGHT SURVEY REPORT OF CARGO IN BULK | Z3: =+A!Z3 | AA3: LOADED
Z4: =+A!Z4 | AA4: UNLOADED
B5: Corporate identification:
A6: =A!B6
B7: Vessel M/V : | Z7: Survey no:
F8: =+A!G12 | AC8: =+A!AG12
A9: FINISHING SOUNDING: | K9: From Hours: | S9: To Hours | AB9: Date: | AJ9: Trim:
K10: =Draft!AS3 | S10: =Draft!AS4 | AB10: =+Draft!AS2 | AJ10: =+Draft!AD13 | AN10: M
S11: Sounding
A12: Compartment Title. | I12: Maximun | N12: Sounding | S12: / ullage | X12: Volume | AD12: Density of | AJ12: Total
B13: * Tank no. | I13: height | N13: / ullage | S13: corrected for | X13: corrected | AD13: Water | AJ13: weight
B14: * Bilges | I14: meausured (*) | N14: metres | S14: trim / list | X14: for trim / list | AD14: in air | AJ14: Metric
B15: * Duct Keel | I15: metres | S15: metres | X15: m3 | AD15: Kg/m3 | AJ15: tonnes
B16: A - BALLAST
B18: =+'Draught survey report'!B18:H18 | I18: =+'Draught survey report'!I18:M18 | N18: =+Deductions!Z11 | X18: =+Deductions!AC11 | AD18: =+Deductions!AF11 | AJ18: =+Deductions!AI11
B19: =+'Draught survey report'!B19:H19 | I19: =+'Draught survey report'!I19:M19 | N19: =+Deductions!Z12 | X19: =+Deductions!AC12 | AD19: =+Deductions!AF12 | AJ19: =+Deductions!AI12
B20: =+'Draught survey report'!B20:H20 | I20: =+'Draught survey report'!I20:M20 | N20: =+Deductions!Z13 | X20: =+Deductions!AC13 | AD20: =+Deductions!AF13 | AJ20: =+Deductions!AI13
B21: =+'Draught survey report'!B21:H21 | I21: =+'Draught survey report'!I21:M21 | N21: =+Deductions!Z14 | X21: =+Deductions!AC14 | AD21: =+Deductions!AF14 | AJ21: =+Deductions!AI14
B22: =+'Draught survey report'!B22:H22 | I22: =+'Draught survey report'!I22:M22 | N22: =+Deductions!Z15 | X22: =+Deductions!AC15 | AD22: =+Deductions!AF15 | AJ22: =+Deductions!AI15
B23: =+'Draught survey report'!B23:H23 | I23: =+'Draught survey report'!I23:M23 | N23: =+Deductions!Z16 | X23: =+Deductions!AC16 | AD23: =+Deductions!AF16 | AJ23: =+Deductions!AI16
B24: =+'Draught survey report'!B24:H24 | I24: =+'Draught survey report'!I24:M24 | N24: =+Deductions!Z17 | X24: =+Deductions!AC17 | AD24: =+Deductions!AF17 | AJ24: =+Deductions!AI17
B25: =+'Draught survey report'!B25:H25 | I25: =+'Draught survey report'!I25:M25 | N25: =+Deductions!Z18 | X25: =+Deductions!AC18 | AD25: =+Deductions!AF18 | AJ25: =+Deductions!AI18
B26: =+'Draught survey report'!B26:H26 | I26: =+'Draught survey report'!I26:M26 | N26: =+Deductions!Z19 | X26: =+Deductions!AC19 | AD26: =+Deductions!AF19 | AJ26: =+Deductions!AI19
B27: =+'Draught survey report'!B27:H27 | I27: =+'Draught survey report'!I27:M27 | N27: =+Deductions!Z20 | X27: =+Deductions!AC20 | AD27: =+Deductions!AF20 | AJ27: =+Deductions!AI20
B28: =+'Draught survey report'!B28:H28 | I28: =+'Draught survey report'!I28:M28 | N28: =+Deductions!Z21 | X28: =+Deductions!AC21 | AD28: =+Deductions!AF21 | AJ28: =+Deductions!AI21
B29: =+'Draught survey report'!B29:H29 | I29: =+'Draught survey report'!I29:M29 | N29: =+Deductions!Z22 | X29: =+Deductions!AC22 | AD29: =+Deductions!AF22 | AJ29: =+Deductions!AI22
... B44: =+'Draught survey report'!B44:H44 | I44: =+'Draught survey report'!I44:M44 | N44: =+Deductions!Z37 | X44: =+Deductions!AC37 | AD44: =+Deductions!AF37 | AJ44: =+Deductions!AI37
B45: Total A | AJ45: =+Deductions!AI42
B46: B - FRESH WATER
B48: =+'Draught survey report'!B48:H48 | I48: =+'Draught survey report'!I48:M48 | N48: =+Deductions!Z47 | X48: =+Deductions!AC47 | AD48: =+Deductions!AF47 | AJ48: =+Deductions!AI47
B49: =+'Draught survey report'!B49:H49 | I49: =+'Draught survey report'!I49:M49 | N49: =+Deductions!Z48 | X49: =+Deductions!AC48 | AD49: =+Deductions!AF48 | AJ49: =+Deductions!AI48
B50: =+'Draught survey report'!B50:H50 | I50: =+'Draught survey report'!I50:M50 | N50: =+Deductions!Z49 | X50: =+Deductions!AC49 | AD50: =+Deductions!AF49 | AJ50: =+Deductions!AI49
B51: =+'Draught survey report'!B51:H51 | I51: =+'Draught survey report'!I51:M51 | N51: =+Deductions!Z50 | X51: =+Deductions!AC50 | AD51: =+Deductions!AF50 | AJ51: =+Deductions!AI50
B52: =+'Draught survey report'!B52:H52 | I52: =+'Draught survey report'!I52:M52 | N52: =+Deductions!Z51 | X52: =+Deductions!AC51 | AD52: =+Deductions!AF51 | AJ52: =+Deductions!AI51
B53: =+'Draught survey report'!B53:H53 | I53: =+'Draught survey report'!I53:M53 | N53: =+Deductions!Z52 | X53: =+Deductions!AC52 | AD53: =+Deductions!AF52 | AJ53: =+Deductions!AI52
B54: Total B | AJ54: =+Deductions!AI54
C56: =IF(Deductions!AC4="X", Deductions!AD4," ")

Sheet D3
A1: U.N. , ECE - DRAUGHT SURVEY CODE
AI2: FORM "D3"
A3: DRAUGHT SURVEY REPORT OF CARGO IN BULK | Z3: =+A!Z3 | AA3: LOADED
Z4: =+A!Z4 | AA4: UNLOADED
B5: Corporate identification:
A6: =A!B6
B7: Vessel M/V : | Z7: Survey no:
F8: =+A!G12 | AC8: =+A!AG12
A9: SOUNDINGS
A11: Compartment | J11: STARTING SURVEY | Z11: FINISHING SURVEY
A12: Title, | F12: Total | J12: Sounding | M12: Temp | O12: Actual | R12: Actual | V12: Weight | Z12: Sounding | AC12: Temp | AE12: Actual | AH12: Actual | AL12: Weight
A13: Tank no. | F13: sounded | J13: Ullage | O13: Density | R13: Volume | V13: Metric | Z13: Ullage | AE13: Density | AH13: Volume | AL13: Metric
A14: Slop t. | F14: depth m. | J14: metres | M14: º C | O14: Kg/m3 | R14: m3 | V14: Tonnes | Z14: metres | AC14: º C | AE14: Kg/m3 | AH14: m3 | AL14: Tonnes
B15: C - FUEL OIL
V17: =ROUND(R17*(O17-(0.00063*(M17-15))),2) | AL17: =ROUND(AH17*(AE17-(0.00063*(AC17-15))),2)
V18: =ROUND(R18*(O18-(0.00063*(M18-15))),2) | AL18: =ROUND(AH18*(AE18-(0.00063*(AC18-15))),2)
V19: =ROUND(R19*(O19-(0.00063*(M19-15))),2) | AL19: =ROUND(AH19*(AE19-(0.00063*(AC19-15))),2)
V20: =ROUND(R20*(O20-(0.00063*(M20-15))),2) | AL20: =ROUND(AH20*(AE20-(0.00063*(AC20-15))),2)
V21: =ROUND(R21*(O21-(0.00063*(M21-15))),2) | AL21: =ROUND(AH21*(AE21-(0.00063*(AC21-15))),2)
V22: =ROUND(R22*(O22-(0.00063*(M22-15))),2) | AL22: =ROUND(AH22*(AE22-(0.00063*(AC22-15))),2)
V23: =ROUND(R23*(O23-(0.00063*(M23-15))),2) | AL23: =ROUND(AH23*(AE23-(0.00063*(AC23-15))),2)
V24: =ROUND(R24*(O24-(0.00063*(M24-15))),2) | AL24: =ROUND(AH24*(AE24-(0.00063*(AC24-15))),2)
V25: =ROUND(R25*(O25-(0.00063*(M25-15))),2) | AL25: =ROUND(AH25*(AE25-(0.00063*(AC25-15))),2)
V26: =ROUND(R26*(O26-(0.00063*(M26-15))),2) | AL26: =ROUND(AH26*(AE26-(0.00063*(AC26-15))),2)
V27: =ROUND(R27*(O27-(0.00063*(M27-15))),2) | AL27: =ROUND(AH27*(AE27-(0.00063*(AC27-15))),2)
V28: =ROUND(R28*(O28-(0.00063*(M28-15))),2) | AL28: =ROUND(AH28*(AE28-(0.00063*(AC28-15))),2)
... V30: =ROUND(R30*(O30-(0.00063*(M30-15))),2) | AL30: =ROUND(AH30*(AE30-(0.00063*(AC30-15))),2)
A31: Total C | V31: =IF(Draft!G20=0,SUM(V17:Y30),Draft!G20) | AL31: =IF(Draft!AS20=0,SUM(AL17:AO30),Draft!AS20)
B32: D - DIESEL OIL
V34: =ROUND(R34*(O34-(0.00065*(M34-15))),2) | AL34: =ROUND(AH34*(AE34-(0.00065*(AC34-15))),2)
V35: =ROUND(R35*(O35-(0.00065*(M35-15))),2) | AL35: =ROUND(AH35*(AE35-(0.00065*(AC35-15))),2)
V36: =ROUND(R36*(O36-(0.00065*(M36-15))),2) | AL36: =ROUND(AH36*(AE36-(0.00065*(AC36-15))),2)
V37: =ROUND(R37*(O37-(0.00065*(M37-15))),2) | AL37: =ROUND(AH37*(AE37-(0.00065*(AC37-15))),2)
V38: =ROUND(R38*(O38-(0.00065*(M38-15))),2) | AL38: =ROUND(AH38*(AE38-(0.00065*(AC38-15))),2)
V39: =ROUND(R39*(O39-(0.00065*(M39-15))),2) | AL39: =ROUND(AH39*(AE39-(0.00065*(AC39-15))),2)
A40: Total D | V40: =IF(Draft!G21=0,SUM(V34:Y39),Draft!G21) | AL40: =IF(Draft!AS21=0,SUM(AL34:AO39),Draft!AS21)
A42: SUMMARY OF DEDUCTIBLES
N43: STARTING SURVEY | Z43: FINISHING SURVEY
N44: metric tonnes | Z44: metric tonnes
A45: Ballast water | O45: =+Draft!G18 | AA45: =+Draft!AS18
...

Sheet Note of Protest SHORE SCALE 
A6: LETTER OF APPARENT DISCREPANCY
A8: VESSEL | E8: : | F8: =Draft!AB1
A9: DATE | E9: : | F9: =Draft!AS2
A10: PORT | E10: : | F10: PUERTO MOIN - COSTA RICA
A11: BERTH | E11: : | F11: 5/3
A12: PRODUCT | E12: : | F12: YELLOW CORN
A13: PRINCIPALS | E13: : | F13: NOMBRE EL OWNER
A15: TO: FERTICA S.A. | B15: CARGUILL
A18: Mrss:
A19: We have been appointed as surveyors on the above named vessel by our principals and acting for and on their
A20: behalf, we do hereby note of protest with you concerning:
A23: =Draft!AB2
A24: BILL OF LADING | J24: 6000 | S24: MT
A25: CARGO DISCHARGED BY SHORE SCALE | J25: 6069.22 | S25: MT
A26: DIFFERENCE | J26: =+J25-J24 | S26: MT
A27: PERCENTAGE % | J27: =+J26/J24 | S27: MT
A30: We hereby reserve the right to this matter at letter of protest date and to take such actions as may be deemed necessary.
A32: Your´s faithfully | R32: RECEIVED by (Signature / Stamp)
A36: MSL Surveyor | R36: Cargo Receivers Representative
A40: Agent - Marinsa | R40: Vessel Representative

Sheet Note of Protest DRAFT
A6: LETTER OF APPARENT DISCREPANCY
A8: VESSEL | E8: : | F8: =Draft!AB1
A9: DATE | E9: : | F9: =Draft!AS2
A10: PORT | E10: : | F10: PUERTO MOIN - COSTA RICA
A11: BERTH | E11: : | F11: 5/3
A12: PRODUCT | E12: : | F12: ='Note of Protest SHORE SCALE '!A23
A13: PRINCIPALS | E13: : | F13: ='Note of Protest SHORE SCALE '!F13
A15: TO: FERTICA S.A. | B15: ='Note of Protest SHORE SCALE '!B15
A18: Mrss:
A19: We have been appointed as surveyors on the above named vessel by our principals and acting for and on their
A20: behalf, we do hereby note of protest with you concerning:
A23: =Draft!AB2
A24: BILL OF LADING | J24: =Draft!AG35 | S24: MT
A25: CARGO DISCHARGED BY DRAFT SURVEY | J25: =Draft!AG34 | S25: MT
A26: DIFFERENCE | J26: =+J25-J24 | S26: MT
A27: PERCENTAGE % | J27: =+J26/J24 | S27: MT
A30: We hereby reserve the right to this matter at letter of protest date and to take such actions as may be deemed necessary.
A32: Your´s faithfully | R32: RECEIVED by (Signature / Stamp)
A36: MSL Surveyor | R36: Cargo Receivers Representative
A40: Agent - Marinsa | R40: Vessel Representative
